Workbook

Sheet Prediction
A1: Date | B1: Grade | C1: Quantity(m3) | D1: No of transit mixers | E1: Client | F1: cement | G1: sand | H1: Revenue | I1: Total Quantity | M1: Row Labels | N1: Sum of cement | O1: Sum of sand | Q1: Cement | T1: Day | U1: Cement | V1: Moving average C | W1: Sand | X1: Moving average
A2: 45689 | B2: M25 | C2: 3.5 | D2: 1 | E2: Client79 | F2: =VLOOKUP(Prediction!B2,Data!$A$1:$F$7,2,)*C2*D2/1000 -> 0.805 | G2: =VLOOKUP(B2,Data!$A$1:$F$7,4,FALSE)*C2*D2/1000 -> 2.352 | H2: =VLOOKUP(B2,Data!$A$1:$G$7,7,FALSE)*C2 -> 17500 | I2: =C2*D2 -> 3.5 | L2: 1 | M2: 45689 | N2: 1.38 | O2: 4.032 | P2: M | Q2: Q1 | R2: =_xlfn.QUARTILE.EXC(N2:N98,1) -> 6.82 | T2: 1 | U2: 1.38 | V2: =U2 -> 1.38 | W2: 4.032 | X2: =W2 -> 4.032
A3: 45689 | B3: M25 | C3: 2.5 | D3: 1 | E3: Client79 | F3: =VLOOKUP(Prediction!B3,Data!$A$1:$F$7,2,)*C3*D3/1000 -> 0.575 | G3: =VLOOKUP(B3,Data!$A$1:$F$7,4,FALSE)*C3*D3/1000 -> 1.68 | H3: =VLOOKUP(B3,Data!$A$1:$G$7,7,FALSE)*C3 -> 12500 | I3: =C3*D3 -> 2.5 | L3: =L2+1 -> 2 | M3: 45690 | N3: 3.335 | O3: 9.744 | Q3: Q3 | R3: =_xlfn.QUARTILE.EXC(N2:N98,3) -> 18.72 | T3: =T2+1 -> 2 | U3: 3.335 | V3: =AVERAGE(U2:U3) -> 2.3575 | W3: 9.744 | X3: =AVERAGE(W2:W3) -> 6.888
A4: 45690 | B4: M25 | C4: 7.25 | D4: 2 | E4: Client19 | F4: =VLOOKUP(Prediction!B4,Data!$A$1:$F$7,2,)*C4*D4/1000 -> 3.335 | G4: =VLOOKUP(B4,Data!$A$1:$F$7,4,FALSE)*C4*D4/1000 -> 9.744 | H4: =VLOOKUP(B4,Data!$A$1:$G$7,7,FALSE)*C4 -> 36250 | I4: =C4*D4 -> 14.5 | L4: =L3+1 -> 3 | M4: 45692 | N4: 14.785 | O4: 32.432 | Q4: IQR | R4: =R3-R2 -> 11.9 | T4: =T3+1 -> 3 | U4: 14.785 | V4: =AVERAGE(U2:U4) -> 6.5 | W4: 32.432 | X4: =AVERAGE(W2:W4) -> 15.402667
A5: 45692 | B5: M30 | C5: 5.5 | D5: 1 | E5: Client21 | F5: =VLOOKUP(Prediction!B5,Data!$A$1:$F$7,2,)*C5*D5/1000 -> 1.375 | G5: =VLOOKUP(B5,Data!$A$1:$F$7,4,FALSE)*C5*D5/1000 -> 4.488 | H5: =VLOOKUP(B5,Data!$A$1:$G$7,7,FALSE)*C5 -> 28600 | I5: =C5*D5 -> 5.5 | L5: =L4+1 -> 4 | M5: 45693 | N5: 24.71 | O5: 50.71 | Q5: lowe limit | R5: =R2-1.5*R4 -> -11.03 | T5: =T4+1 -> 4 | U5: 24.71 | V5: =AVERAGE(U2:U5) -> 11.0525 | W5: 50.71 | X5: =AVERAGE(W2:W5) -> 24.2295
A6: 45692 | B6: M30 | C6: 5 | D6: 1 | E6: Client21 | F6: =VLOOKUP(Prediction!B6,Data!$A$1:$F$7,2,)*C6*D6/1000 -> 1.25 | G6: =VLOOKUP(B6,Data!$A$1:$F$7,4,FALSE)*C6*D6/1000 -> 4.08 | H6: =VLOOKUP(B6,Data!$A$1:$G$7,7,FALSE)*C6 -> 26000 | I6: =C6*D6 -> 5 | L6: =L5+1 -> 5 | M6: 45696 | N6: 26.64 | O6: 62.137 | Q6: upper limit | R6: =R3+1.5*R4 -> 36.57 | T6: =T5+1 -> 5 | U6: 26.64 | V6: =AVERAGE(U2:U6) -> 14.17 | W6: 62.137 | X6: =AVERAGE(W2:W6) -> 31.811
A7: 45692 | B7: M20 | C7: 7 | D7: 5 | E7: Client42 | F7: =VLOOKUP(Prediction!B7,Data!$A$1:$F$7,2,)*C7*D7/1000 -> 11.2 | G7: =VLOOKUP(B7,Data!$A$1:$F$7,4,FALSE)*C7*D7/1000 -> 21.98 | H7: =VLOOKUP(B7,Data!$A$1:$G$7,7,FALSE)*C7 -> 32900 | I7: =C7*D7 -> 35 | L7: =L6+1 -> 6 | M7: 45697 | N7: 24.01 | O7: 54.201 | T7: =T6+1 -> 6 | U7: 24.01 | V7: =AVERAGE(U2:U7) -> 15.81 | W7: 54.201 | X7: =AVERAGE(W2:W7) -> 35.542667
A8: 45692 | B8: M20 | C8: 3 | D8: 1 | E8: Client42 | F8: =VLOOKUP(Prediction!B8,Data!$A$1:$F$7,2,)*C8*D8/1000 -> 0.96 | G8: =VLOOKUP(B8,Data!$A$1:$F$7,4,FALSE)*C8*D8/1000 -> 1.884 | H8: =VLOOKUP(B8,Data!$A$1:$G$7,7,FALSE)*C8 -> 14100 | I8: =C8*D8 -> 3 | L8: =L7+1 -> 7 | M8: 45698 | N8: 11.03 | O8: 23.632 | Q8: sand | T8: =T7+1 -> 7 | U8: 11.03 | V8: =AVERAGE(U2:U8) -> 15.127143 | W8: 23.632 | X8: =AVERAGE(W2:W8) -> 33.841143
A9: 45693 | B9: M20 | C9: 7 | D9: 5 | E9: Client81 | F9: =VLOOKUP(Prediction!B9,Data!$A$1:$F$7,2,)*C9*D9/1000 -> 11.2 | G9: =VLOOKUP(B9,Data!$A$1:$F$7,4,FALSE)*C9*D9/1000 -> 21.98 | H9: =VLOOKUP(B9,Data!$A$1:$G$7,7,FALSE)*C9 -> 32900 | I9: =C9*D9 -> 35 | L9: =L8+1 -> 8 | M9: 45699 | N9: 9.24 | O9: 27.244 | Q9: Q1 | R9: =_xlfn.QUARTILE.EXC(O2:O98,1) -> 16.128 | T9: =T8+1 -> 8 | U9: 9.24 | V9: =AVERAGE(U3:U9) -> 16.25 | W9: 27.244 | X9: =AVERAGE(W3:W9) -> 37.157143
A10: 45693 | B10: M30 | C10: 3 | D10: 1 | E10: Client81 | F10: =VLOOKUP(Prediction!B10,Data!$A$1:$F$7,2,)*C10*D10/1000 -> 0.75 | G10: =VLOOKUP(B10,Data!$A$1:$F$7,4,FALSE)*C10*D10/1000 -> 2.448 | H10: =VLOOKUP(B10,Data!$A$1:$G$7,7,FALSE)*C10 -> 15600 | I10: =C10*D10 -> 3 | L10: =L9+1 -> 9 | M10: 45700 | N10: 22.75 | O10: 74.256 | Q10: Q3 | R10: =_xlfn.QUARTILE.EXC(O2:O98,3) -> 51.66 | T10: =T9+1 -> 9 | U10: 22.75 | V10: =AVERAGE(U4:U10) -> 19.023571 | W10: 74.256 | X10: =AVERAGE(W4:W10) -> 46.373143
A11: 45693 | B11: M20 | C11: 7 | D11: 5 | E11: Client67 | F11: =VLOOKUP(Prediction!B11,Data!$A$1:$F$7,2,)*C11*D11/1000 -> 11.2 | G11: =VLOOKUP(B11,Data!$A$1:$F$7,4,FALSE)*C11*D11/1000 -> 21.98 | H11: =VLOOKUP(B11,Data!$A$1:$G$7,7,FALSE)*C11 -> 32900 | I11: =C11*D11 -> 35 | L11: =L10+1 -> 10 | M11: 45701 | N11: 13.125 | O11: 42.84 | Q11: IQR | R11: =R10-R9 -> 35.532 | T11: =T10+1 -> 10 | U11: 13.125 | V11: =AVERAGE(U5:U11) -> 18.786429 | W11: 42.84 | X11: =AVERAGE(W5:W11) -> 47.86
A12: 45693 | B12: M15 | C12: 6 | D12: 1 | E12: Client60 | F12: =VLOOKUP(Prediction!B12,Data!$A$1:$F$7,2,)*C12*D12/1000 -> 1.56 | G12: =VLOOKUP(B12,Data!$A$1:$F$7,4,FALSE)*C12*D12/1000 -> 4.302 | H12: =VLOOKUP(B12,Data!$A$1:$G$7,7,FALSE)*C12 -> 25800 | I12: =C12*D12 -> 6 | L12: =L11+1 -> 11 | M12: 45702 | N12: 36.05 | O12: 115.3635 | Q12: Lower limit | R12: =R9-1.5*R11 -> -37.17 | T12: =T11+1 -> 11 | U12: 3.475 | V12: =AVERAGE(U6:U12) -> 15.752857 | W12: 10.752 | X12: =AVERAGE(W6:W12) -> 42.151714
A13: 45696 | B13: M20 | C13: 7 | D13: 2 | E13: Client47 | F13: =VLOOKUP(Prediction!B13,Data!$A$1:$F$7,2,)*C13*D13/1000 -> 4.48 | G13: =VLOOKUP(B13,Data!$A$1:$F$7,4,FALSE)*C13*D13/1000 -> 8.792 | H13: =VLOOKUP(B13,Data!$A$1:$G$7,7,FALSE)*C13 -> 32900 | I13: =C13*D13 -> 14 | L13: =L12+1 -> 12 | M13: 45703 | N13: 3.475 | O13: 10.752 | Q13: upper limit | R13: =R10+1.5*R11 -> 104.958 | T13: =T12+1 -> 12 | U13: 1.955 | V13: =AVERAGE(U7:U13) -> 12.226429 | W13: 5.712 | X13: =AVERAGE(W7:W13) -> 34.091
A14: 45696 | B14: M20 | C14: 3 | D14: 1 | E14: Client47 | F14: =VLOOKUP(Prediction!B14,Data!$A$1:$F$7,2,)*C14*D14/1000 -> 0.96 | G14: =VLOOKUP(B14,Data!$A$1:$F$7,4,FALSE)*C14*D14/1000 -> 1.884 | H14: =VLOOKUP(B14,Data!$A$1:$G$7,7,FALSE)*C14 -> 14100 | I14: =C14*D14 -> 3 | L14: =L13+1 -> 13 | M14: 45704 | N14: 1.955 | O14: 5.712 | T14: =T13+1 -> 13 | U14: 9.2 | V14: =AVERAGE(U8:U14) -> 10.110714 | W14: 26.88 | X14: =AVERAGE(W8:W14) -> 30.188
A15: 45696 | B15: M20 | C15: 7 | D15: 6 | E15: Client10 | F15: =VLOOKUP(Prediction!B15,Data!$A$1:$F$7,2,)*C15*D15/1000 -> 13.44 | G15: =VLOOKUP(B15,Data!$A$1:$F$7,4,FALSE)*C15*D15/1000 -> 26.376 | H15: =VLOOKUP(B15,Data!$A$1:$G$7,7,FALSE)*C15 -> 32900 | I15: =C15*D15 -> 42 | L15: =L14+1 -> 14 | M15: 45705 | N15: 9.2 | O15: 26.88 | T15: =T14+1 -> 14 | U15: 9.94 | V15: =AVERAGE(U9:U15) -> 9.955 | W15: 22.596 | X15: =AVERAGE(W9:W15) -> 30.04
A16: 45696 | B16: M20 | C16: 4 | D16: 1 | E16: Client10 | F16: =VLOOKUP(Prediction!B16,Data!$A$1:$F$7,2,)*C16*D16/1000 -> 1.28 | G16: =VLOOKUP(B16,Data!$A$1:$F$7,4,FALSE)*C16*D16/1000 -> 2.512 | H16: =VLOOKUP(B16,Data!$A$1:$G$7,7,FALSE)*C16 -> 18800 | I16: =C16*D16 -> 4 | L16: =L15+1 -> 15 | M16: 45706 | N16: 9.94 | O16: 22.596 | Q16: Predction(Day NO | R16: cement | S16: Sand | T16: =T15+1 -> 15 | U16: 15.4 | V16: =AVERAGE(U10:U16) -> 10.835 | W16: 36.4 | X16: =AVERAGE(W10:W16) -> 31.348
A17: 45696 | B17: M20 | C17: 1 | D17: 1 | E17: Client10 | F17: =VLOOKUP(Prediction!B17,Data!$A$1:$F$7,2,)*C17*D17/1000 -> 0.32 | G17: =VLOOKUP(B17,Data!$A$1:$F$7,4,FALSE)*C17*D17/1000 -> 0.628 | H17: =VLOOKUP(B17,Data!$A$1:$G$7,7,FALSE)*C17 -> 4700 | I17: =C17*D17 -> 1 | L17: =L16+1 -> 16 | M17: 45707 | N17: 15.4 | O17: 36.4 | Q17: 99 | R17: =(-2*10^-7)*Q17^3 + 0.008*Q17^2 - 0.0186*Q17 + 11.073 -> 87.44554 | S17: =(2*10^-5)*Q17^3-0.0006*Q17^2+0.0905*Q17+26.522 -> 49.00688 | T17: =T16+1 -> 16 | U17: 10.71 | V17: =AVERAGE(U11:U17) -> 9.115 | W17: 23.296 | X17: =AVERAGE(W11:W17) -> 24.068
A18: 45696 | B18: M10 | C18: 7 | D18: 3 | E18: Client80 | F18: =VLOOKUP(Prediction!B18,Data!$A$1:$F$7,2,)*C18*D18/1000 -> 4.41 | G18: =VLOOKUP(B18,Data!$A$1:$F$7,4,FALSE)*C18*D18/1000 -> 16.233 | H18: =VLOOKUP(B18,Data!$A$1:$G$7,7,FALSE)*C18 -> 28000 | I18: =C18*D18 -> 21 | L18: =L17+1 -> 17 | M18: 45708 | N18: 10.71 | O18: 23.296 | Q18: 100 | R18: =(-2*10^-7)*Q18^3 + 0.008*Q18^2 - 0.0186*Q18 + 11.073 -> 89.013 | S18: =(2*10^-5)*Q18^3-0.0006*Q18^2+0.0905*Q18+26.522 -> 49.572 | T18: =T17+1 -> 17 | U18: 20.835 | V18: =AVERAGE(U12:U18) -> 10.216429 | W18: 51.3215 | X18: =AVERAGE(W12:W18) -> 25.279643
A19: 45696 | B19: M30 | C19: 7 | D19: 1 | E19: Client60 | F19: =VLOOKUP(Prediction!B19,Data!$A$1:$F$7,2,)*C19*D19/1000 -> 1.75 | G19: =VLOOKUP(B19,Data!$A$1:$F$7,4,FALSE)*C19*D19/1000 -> 5.712 | H19: =VLOOKUP(B19,Data!$A$1:$G$7,7,FALSE)*C19 -> 36400 | I19: =C19*D19 -> 7 | L19: =L18+1 -> 18 | M19: 45709 | N19: 20.835 | O19: 51.3215 | Q19: 101 | R19: =(-2*10^-7)*Q19^3 + 0.008*Q19^2 - 0.0186*Q19 + 11.073 -> 90.59634 | S19: =(2*10^-5)*Q19^3-0.0006*Q19^2+0.0905*Q19+26.522 -> 50.14792 | T19: =T18+1 -> 18 | U19: 10.61 | V19: =AVERAGE(U13:U19) -> 11.235714 | W19: 25.052 | X19: =AVERAGE(W13:W19) -> 27.3225
A20: 45697 | B20: M10 | C20: 7 | D20: 1 | E20: Client80 | F20: =VLOOKUP(Prediction!B20,Data!$A$1:$F$7,2,)*C20*D20/1000 -> 1.47 | G20: =VLOOKUP(B20,Data!$A$1:$F$7,4,FALSE)*C20*D20/1000 -> 5.411 | H20: =VLOOKUP(B20,Data!$A$1:$G$7,7,FALSE)*C20 -> 28000 | I20: =C20*D20 -> 7 | L20: =L19+1 -> 19 | M20: 45710 | N20: 10.61 | O20: 25.052 | Q20: 102 | R20: =(-2*10^-7)*Q20^3 + 0.008*Q20^2 - 0.0186*Q20 + 11.073 -> 92.195558 | S20: =(2*10^-5)*Q20^3-0.0006*Q20^2+0.0905*Q20+26.522 -> 50.73476 | T20: =T19+1 -> 19 | U20: 3.09 | V20: =AVERAGE(U14:U20) -> 11.397857 | W20: 9.456 | X20: =AVERAGE(W14:W20) -> 27.857357
A21: 45697 | B21: M30 | C21: 7 | D21: 1 | E21: Client60 | F21: =VLOOKUP(Prediction!B21,Data!$A$1:$F$7,2,)*C21*D21/1000 -> 1.75 | G21: =VLOOKUP(B21,Data!$A$1:$F$7,4,FALSE)*C21*D21/1000 -> 5.712 | H21: =VLOOKUP(B21,Data!$A$1:$G$7,7,FALSE)*C21 -> 36400 | I21: =C21*D21 -> 7 | L21: =L20+1 -> 20 | M21: 45711 | N21: 3.09 | O21: 9.456 | Q21: 103 | R21: =(-2*10^-7)*Q21^3 + 0.008*Q21^2 - 0.0186*Q21 + 11.073 -> 93.810655 | S21: =(2*10^-5)*Q21^3-0.0006*Q21^2+0.0905*Q21+26.522 -> 51.33264 | T21: =T20+1 -> 20 | U21: 6.51 | V21: =AVERAGE(U15:U21) -> 11.013571 | W21: 15.936 | X21: =AVERAGE(W15:W21) -> 26.293929
A22: 45697 | B22: M20 | C22: 5 | D22: 1 | E22: Client7 | F22: =VLOOKUP(Prediction!B22,Data!$A$1:$F$7,2,)*C22*D22/1000 -> 1.6 | G22: =VLOOKUP(B22,Data!$A$1:$F$7,4,FALSE)*C22*D22/1000 -> 3.14 | H22: =VLOOKUP(B22,Data!$A$1:$G$7,7,FALSE)*C22 -> 23500 | I22: =C22*D22 -> 5 | L22: =L21+1 -> 21 | M22: 45712 | N22: 6.51 | O22: 15.936 | Q22: 104 | R22: =(-2*10^-7)*Q22^3 + 0.008*Q22^2 - 0.0186*Q22 + 11.073 -> 95.441627 | S22: =(2*10^-5)*Q22^3-0.0006*Q22^2+0.0905*Q22+26.522 -> 51.94168 | T22: =T21+1 -> 21 | U22: 3.94 | V22: =AVERAGE(U16:U22) -> 10.156429 | W22: 13.106 | X22: =AVERAGE(W16:W22) -> 24.938214
A23: 45697 | B23: M20 | C23: 4.5 | D23: 1 | E23: Client47 | F23: =VLOOKUP(Prediction!B23,Data!$A$1:$F$7,2,)*C23*D23/1000 -> 1.44 | G23: =VLOOKUP(B23,Data!$A$1:$F$7,4,FALSE)*C23*D23/1000 -> 2.826 | H23: =VLOOKUP(B23,Data!$A$1:$G$7,7,FALSE)*C23 -> 21150 | I23: =C23*D23 -> 4.5 | L23: =L22+1 -> 22 | M23: 45713 | N23: 3.94 | O23: 13.106 | T23: =T22+1 -> 22 | U23: 14.435 | V23: =AVERAGE(U17:U23) -> 10.018571 | W23: 37.357 | X23: =AVERAGE(W17:W23) -> 25.074929
A24: 45697 | B24: M20 | C24: 7 | D24: 5 | E24: Client71 | F24: =VLOOKUP(Prediction!B24,Data!$A$1:$F$7,2,)*C24*D24/1000 -> 11.2 | G24: =VLOOKUP(B24,Data!$A$1:$F$7,4,FALSE)*C24*D24/1000 -> 21.98 | H24: =VLOOKUP(B24,Data!$A$1:$G$7,7,FALSE)*C24 -> 32900 | I24: =C24*D24 -> 35 | L24: =L23+1 -> 23 | M24: 45714 | N24: 14.435 | O24: 37.357 | S24: Scaled San | T24: =T23+1 -> 23 | U24: 10.66 | V24: =AVERAGE(U18:U24) -> 10.011429 | W24: 29.397 | X24: =AVERAGE(W18:W24) -> 25.9465
A25: 45697 | B25: M20 | C25: 2 | D25: 1 | E25: Client71 | F25: =VLOOKUP(Prediction!B25,Data!$A$1:$F$7,2,)*C25*D25/1000 -> 0.64 | G25: =VLOOKUP(B25,Data!$A$1:$F$7,4,FALSE)*C25*D25/1000 -> 1.256 | H25: =VLOOKUP(B25,Data!$A$1:$G$7,7,FALSE)*C25 -> 9400 | I25: =C25*D25 -> 2 | L25: =L24+1 -> 24 | M25: 45715 | N25: 10.66 | O25: 29.397 | S25: =2.4*S17 -> 117.61651 | T25: =T24+1 -> 24 | U25: 12.74 | V25: =AVERAGE(U19:U25) -> 8.855 | W25: 35.133 | X25: =AVERAGE(W19:W25) -> 23.633857
A26: 45697 | B26: M20 | C26: 6.5 | D26: 2 | E26: Client37 | F26: =VLOOKUP(Prediction!B26,Data!$A$1:$F$7,2,)*C26*D26/1000 -> 4.16 | G26: =VLOOKUP(B26,Data!$A$1:$F$7,4,FALSE)*C26*D26/1000 -> 8.164 | H26: =VLOOKUP(B26,Data!$A$1:$G$7,7,FALSE)*C26 -> 30550 | I26: =C26*D26 -> 13 | L26: =L25+1 -> 25 | M26: 45716 | N26: 12.74 | O26: 35.133 | S26: =2.4*S18 -> 118.9728 | T26: =T25+1 -> 25 | U26: 18.06 | V26: =AVERAGE(U20:U26) -> 9.9192857 | W26: 51.576 | X26: =AVERAGE(W20:W26) -> 27.423
A27: 45697 | B27: M30 | C27: 7 | D27: 1 | E27: Client60 | F27: =VLOOKUP(Prediction!B27,Data!$A$1:$F$7,2,)*C27*D27/1000 -> 1.75 | G27: =VLOOKUP(B27,Data!$A$1:$F$7,4,FALSE)*C27*D27/1000 -> 5.712 | H27: =VLOOKUP(B27,Data!$A$1:$G$7,7,FALSE)*C27 -> 36400 | I27: =C27*D27 -> 7 | L27: =L26+1 -> 26 | M27: 45717 | N27: 18.06 | O27: 51.576 | S27: =2.4*S19 -> 120.35501 | T27: =T26+1 -> 26 | U27: 9.1 | V27: =AVERAGE(U21:U27) -> 10.777857 | W27: 25.095 | X27: =AVERAGE(W21:W27) -> 29.657143
A28: 45698 | B28: M25 | C28: 6 | D28: 1 | E28: Client2 | F28: =VLOOKUP(Prediction!B28,Data!$A$1:$F$7,2,)*C28*D28/1000 -> 1.38 | G28: =VLOOKUP(B28,Data!$A$1:$F$7,4,FALSE)*C28*D28/1000 -> 4.032 | H28: =VLOOKUP(B28,Data!$A$1:$G$7,7,FALSE)*C28 -> 30000 | I28: =C28*D28 -> 6 | L28: =L27+1 -> 27 | M28: 45718 | N28: 9.1 | O28: 25.095 | S28: =2.4*S20 -> 121.76342 | T28: =T27+1 -> 27 | U28: 6.72 | V28: =AVERAGE(U22:U28) -> 10.807857 | W28: 13.188 | X28: =AVERAGE(W22:W28) -> 29.264571
A29: 45698 | B29: M25 | C29: 3 | D29: 1 | E29: Client2 | F29: =VLOOKUP(Prediction!B29,Data!$A$1:$F$7,2,)*C29*D29/1000 -> 0.69 | G29: =VLOOKUP(B29,Data!$A$1:$F$7,4,FALSE)*C29*D29/1000 -> 2.016 | H29: =VLOOKUP(B29,Data!$A$1:$G$7,7,FALSE)*C29 -> 15000 | I29: =C29*D29 -> 3 | L29: =L28+1 -> 28 | M29: 45719 | N29: 6.72 | O29: 13.188 | S29: =2.4*S21 -> 123.19834 | T29: =T28+1 -> 28 | U29: 12.76 | V29: =AVERAGE(U23:U29) -> 12.067857 | W29: 34.152 | X29: =AVERAGE(W23:W29) -> 32.271143
A30: 45698 | B30: M20 | C30: 7 | D30: 4 | E30: Client42 | F30: =VLOOKUP(Prediction!B30,Data!$A$1:$F$7,2,)*C30*D30/1000 -> 8.96 | G30: =VLOOKUP(B30,Data!$A$1:$F$7,4,FALSE)*C30*D30/1000 -> 17.584 | H30: =VLOOKUP(B30,Data!$A$1:$G$7,7,FALSE)*C30 -> 32900 | I30: =C30*D30 -> 28 | L30: =L29+1 -> 29 | M30: 45720 | N30: 12.76 | O30: 34.152 | S30: =2.4*S22 -> 124.66003 | T30: =T29+1 -> 29 | U30: 10.99 | V30: =AVERAGE(U24:U30) -> 11.575714 | W30: 32.956 | X30: =AVERAGE(W24:W30) -> 31.642429
A31: 45699 | B31: M20 | C31: 7 | D31: 1 | E31: Client42 | F31: =VLOOKUP(Prediction!B31,Data!$A$1:$F$7,2,)*C31*D31/1000 -> 2.24 | G31: =VLOOKUP(B31,Data!$A$1:$F$7,4,FALSE)*C31*D31/1000 -> 4.396 | H31: =VLOOKUP(B31,Data!$A$1:$G$7,7,FALSE)*C31 -> 32900 | I31: =C31*D31 -> 7 | L31: =L30+1 -> 30 | M31: 45722 | N31: 10.99 | O31: 32.956 | T31: =T30+1 -> 30 | U31: 17.605 | V31: =AVERAGE(U25:U31) -> 12.567857 | W31: 43.258 | X31: =AVERAGE(W25:W31) -> 33.622571
A32: 45699 | B32: M30 | C32: 7 | D32: 4 | E32: Client80 | F32: =VLOOKUP(Prediction!B32,Data!$A$1:$F$7,2,)*C32*D32/1000 -> 7 | G32: =VLOOKUP(B32,Data!$A$1:$F$7,4,FALSE)*C32*D32/1000 -> 22.848 | H32: =VLOOKUP(B32,Data!$A$1:$G$7,7,FALSE)*C32 -> 36400 | I32: =C32*D32 -> 28 | L32: =L31+1 -> 31 | M32: 45723 | N32: 17.605 | O32: 43.258 | T32: =T31+1 -> 31 | U32: 14.92 | V32: =AVERAGE(U26:U32) -> 12.879286 | W32: 34.088 | X32: =AVERAGE(W26:W32) -> 33.473286
A33: 45700 | B33: M30 | C33: 7 | D33: 10 | E33: Client80 | F33: =VLOOKUP(Prediction!B33,Data!$A$1:$F$7,2,)*C33*D33/1000 -> 17.5 | G33: =VLOOKUP(B33,Data!$A$1:$F$7,4,FALSE)*C33*D33/1000 -> 57.12 | H33: =VLOOKUP(B33,Data!$A$1:$G$7,7,FALSE)*C33 -> 36400 | I33: =C33*D33 -> 70 | L33: =L32+1 -> 32 | M33: 45724 | N33: 14.92 | O33: 34.088 | T33: =T32+1 -> 32 | U33: 8.05 | V33: =AVERAGE(U27:U33) -> 11.449286 | W33: 23.52 | X33: =AVERAGE(W27:W33) -> 29.465286
A34: 45700 | B34: M30 | C34: 7 | D34: 3 | E34: Client60 | F34: =VLOOKUP(Prediction!B34,Data!$A$1:$F$7,2,)*C34*D34/1000 -> 5.25 | G34: =VLOOKUP(B34,Data!$A$1:$F$7,4,FALSE)*C34*D34/1000 -> 17.136 | H34: =VLOOKUP(B34,Data!$A$1:$G$7,7,FALSE)*C34 -> 36400 | I34: =C34*D34 -> 21 | L34: =L33+1 -> 33 | M34: 45725 | N34: 8.05 | O34: 23.52 | T34: =T33+1 -> 33 | U34: 1.28 | V34: =AVERAGE(U28:U34) -> 10.332143 | W34: 2.512 | X34: =AVERAGE(W28:W34) -> 26.239143
A35: 45701 | B35: M30 | C35: 7 | D35: 5 | E35: Client80 | F35: =VLOOKUP(Prediction!B35,Data!$A$1:$F$7,2,)*C35*D35/1000 -> 8.75 | G35: =VLOOKUP(B35,Data!$A$1:$F$7,4,FALSE)*C35*D35/1000 -> 28.56 | H35: =VLOOKUP(B35,Data!$A$1:$G$7,7,FALSE)*C35 -> 36400 | I35: =C35*D35 -> 35 | L35: =L34+1 -> 34 | M35: 45726 | N35: 1.28 | O35: 2.512 | T35: =T34+1 -> 34 | U35: 5.43 | V35: =AVERAGE(U29:U35) -> 10.147857 | W35: 16.464 | X35: =AVERAGE(W29:W35) -> 26.707143
A36: 45701 | B36: M30 | C36: 7 | D36: 1 | E36: Client60 | F36: =VLOOKUP(Prediction!B36,Data!$A$1:$F$7,2,)*C36*D36/1000 -> 1.75 | G36: =VLOOKUP(B36,Data!$A$1:$F$7,4,FALSE)*C36*D36/1000 -> 5.712 | H36: =VLOOKUP(B36,Data!$A$1:$G$7,7,FALSE)*C36 -> 36400 | I36: =C36*D36 -> 7 | L36: =L35+1 -> 35 | M36: 45727 | N36: 5.43 | O36: 16.464 | T36: =T35+1 -> 35 | U36: 1.25 | V36: =AVERAGE(U30:U36) -> 8.5035714 | W36: 4.08 | X36: =AVERAGE(W30:W36) -> 22.411143
A37: 45701 | B37: M30 | C37: 5 | D37: 1 | E37: Client80 | F37: =VLOOKUP(Prediction!B37,Data!$A$1:$F$7,2,)*C37*D37/1000 -> 1.25 | G37: =VLOOKUP(B37,Data!$A$1:$F$7,4,FALSE)*C37*D37/1000 -> 4.08 | H37: =VLOOKUP(B37,Data!$A$1:$G$7,7,FALSE)*C37 -> 26000 | I37: =C37*D37 -> 5 | L37: =L36+1 -> 36 | M37: 45729 | N37: 1.25 | O37: 4.08 | T37: =T36+1 -> 36 | U37: 12.765 | V37: =AVERAGE(U31:U37) -> 8.7571429 | W37: 37.296 | X37: =AVERAGE(W31:W37) -> 23.031143
A38: 45701 | B38: M30 | C38: 5.5 | D38: 1 | E38: Client80 | F38: =VLOOKUP(Prediction!B38,Data!$A$1:$F$7,2,)*C38*D38/1000 -> 1.375 | G38: =VLOOKUP(B38,Data!$A$1:$F$7,4,FALSE)*C38*D38/1000 -> 4.488 | H38: =VLOOKUP(B38,Data!$A$1:$G$7,7,FALSE)*C38 -> 28600 | I38: =C38*D38 -> 5.5 | L38: =L37+1 -> 37 | M38: 45730 | N38: 12.765 | O38: 37.296 | T38: =T37+1 -> 37 | U38: 17.11 | V38: =AVERAGE(U32:U38) -> 8.6864286 | W38: 52.822 | X38: =AVERAGE(W32:W38) -> 24.397429
A39: 45702 | B39: M15 | C39: 7 | D39: 2 | E39: Client50 | F39: =VLOOKUP(Prediction!B39,Data!$A$1:$F$7,2,)*C39*D39/1000 -> 3.64 | G39: =VLOOKUP(B39,Data!$A$1:$F$7,4,FALSE)*C39*D39/1000 -> 10.038 | H39: =VLOOKUP(B39,Data!$A$1:$G$7,7,FALSE)*C39 -> 30100 | I39: =C39*D39 -> 14 | L39: =L38+1 -> 38 | M39: 45732 | N39: 17.11 | O39: 52.822 | T39: =T38+1 -> 38 | U39: 4.255 | V39: =AVERAGE(U33:U39) -> 7.1628571 | W39: 12.432 | X39: =AVERAGE(W33:W39) -> 21.303714
A40: 45702 | B40: M30 | C40: 7 | D40: 15 | E40: Client6 | F40: =VLOOKUP(Prediction!B40,Data!$A$1:$F$7,2,)*C40*D40/1000 -> 26.25 | G40: =VLOOKUP(B40,Data!$A$1:$F$7,4,FALSE)*C40*D40/1000 -> 85.68 | H40: =VLOOKUP(B40,Data!$A$1:$G$7,7,FALSE)*C40 -> 36400 | I40: =C40*D40 -> 105 | L40: =L39+1 -> 39 | M40: 45733 | N40: 4.255 | O40: 12.432 | T40: =T39+1 -> 39 | U40: 6.92 | V40: =AVERAGE(U34:U40) -> 7.0014286 | W40: 15.024 | X40: =AVERAGE(W34:W40) -> 20.09
...

Sheet Data
A1: Mix Designation | B1: Cement (kg/m³) | C1: Flyash(kg/m³) | D1: Sand (kg/m³) | E1: 20mm Coarse Agg. (kg/m³) | F1: 12.5mm Coarse Agg. (kg/m³) | G1: cost per cubic meter
A2: M10 | B2: 210 | C2: 0 | D2: 773 | E2: 660 | F2: 490 | G2: 4000
A3: M15 | B3: 260 | C3: 0 | D3: 717 | E3: 630 | F3: 480 | G3: 4300
A4: M20 | B4: 320 | C4: 80 | D4: 628 | E4: 600 | F4: 470 | G4: 4700
A5: M25 | B5: 230 | C5: 100 | D5: 672 | E5: 595 | F5: 470 | G5: 5000
A6: M30 | B6: 250 | C6: 110 | D6: 816 | E6: 586 | F6: 478 | G6: 5200
A7: M35 | B7: 265 | C7: 115 | D7: 790 | E7: 580 | F7: 470 | G7: 5450

Sheet Customer Classification
A1: Row Labels | B1: Max of Date | C1: Frequency | D1: Sum of Total Quantity | E1: Sum of Revenue | G1: Name | H1: Quantity | I1: Reven | J1: Freq | K1: Max of date | L1: Recency | N1: recency metric | O1: Normalized Recency | P1: Freq | Q1: Volume | R1: Revenue | S1: Score | U1: Client | V1: Score | W1: Segment
A2: Client1 | B2: 45738 | C2: 3 | D2: 21.5 | E2: 64500 | G2: Client1 | H2: 21.5 | I2: 64500 | J2: 3 | K2: 45738 | L2: =$M$2-K2 -> 71 | M2: 45809 | N2: =1/L2 -> 0.014084507 | O2: =N2/MAX($N$2:$N$82) -> 0.042253521 | P2: =J2/MAX($J$2:$J$82) -> 0.069767442 | Q2: =H2/MAX($H$2:$H$82) -> 0.036720751 | R2: =I2/MAX($I$2:$I$82) -> 0.049831962 | S2: =SUM(N2:R2) -> 0.21265818 | T2: 1 | U2: Client60 | V2: 2.9005271 | W2: =IF(V2>=1,"Loyal",IF(V2>=0.4,"Potential Loyalist",IF(V2>=0.15,"Need Attention","At Risk"))) -> Loyal
A3: Client10 | B3: 45696 | C3: 3 | D3: 47 | E3: 56400 | G3: Client2 | H3: 9 | I3: 45000 | J3: 2 | K3: 45698 | L3: =$M$2-K3 -> 111 | N3: =1/L3 -> 0.009009009 | O3: =N3/MAX($N$2:$N$82) -> 0.027027027 | P3: =J3/MAX($J$2:$J$82) -> 0.046511628 | Q3: =H3/MAX($H$2:$H$82) -> 0.015371477 | R3: =I3/MAX($I$2:$I$82) -> 0.034766485 | S3: =SUM(N3:R3) -> 0.13268563 | T3: 2 | U3: Client23 | V3: 2.8983335 | W3: =IF(V3>=1,"Loyal",IF(V3>=0.4,"Potential Loyalist",IF(V3>=0.15,"Need Attention","At Risk"))) -> Loyal
A4: Client11 | B4: 45783 | C4: 1 | D4: 42 | E4: 32900 | G4: Client3 | H4: 12.5 | I4: 62500 | J4: 2 | K4: 45761 | L4: =$M$2-K4 -> 48 | N4: =1/L4 -> 0.020833333 | O4: =N4/MAX($N$2:$N$82) -> 0.0625 | P4: =J4/MAX($J$2:$J$82) -> 0.046511628 | Q4: =H4/MAX($H$2:$H$82) -> 0.021349274 | R4: =I4/MAX($I$2:$I$82) -> 0.048286785 | S4: =SUM(N4:R4) -> 0.19948102 | T4: =T3+1 -> 3 | U4: Client72 | V4: 2.2063317 | W4: =IF(V4>=1,"Loyal",IF(V4>=0.4,"Potential Loyalist",IF(V4>=0.15,"Need Attention","At Risk"))) -> Loyal
A5: Client12 | B5: 45764 | C5: 1 | D5: 16 | E5: 37600 | G5: Client4 | H5: 247.5 | I5: 361400 | J5: 11 | K5: 45742 | L5: =$M$2-K5 -> 67 | N5: =1/L5 -> 0.014925373 | O5: =N5/MAX($N$2:$N$82) -> 0.044776119 | P5: =J5/MAX($J$2:$J$82) -> 0.25581395 | Q5: =H5/MAX($H$2:$H$82) -> 0.42271563 | R5: =I5/MAX($I$2:$I$82) -> 0.2792135 | S5: =SUM(N5:R5) -> 1.0174446 | T5: =T4+1 -> 4 | U5: Client64 | V5: 1.5863605 | W5: =IF(V5>=1,"Loyal",IF(V5>=0.4,"Potential Loyalist",IF(V5>=0.15,"Need Attention","At Risk"))) -> Loyal
A6: Client13 | B6: 45780 | C6: 1 | D6: 4 | E6: 20000 | G6: Client5 | H6: 14 | I6: 36400 | J6: 1 | K6: 45702 | L6: =$M$2-K6 -> 107 | N6: =1/L6 -> 0.0093457944 | O6: =N6/MAX($N$2:$N$82) -> 0.028037383 | P6: =J6/MAX($J$2:$J$82) -> 0.023255814 | Q6: =H6/MAX($H$2:$H$82) -> 0.023911187 | R6: =I6/MAX($I$2:$I$82) -> 0.028122224 | S6: =SUM(N6:R6) -> 0.1126724 | T6: =T5+1 -> 5 | U6: Client56 | V6: 1.3902792 | W6: =IF(V6>=1,"Loyal",IF(V6>=0.4,"Potential Loyalist",IF(V6>=0.15,"Need Attention","At Risk"))) -> Loyal | Z6: Segment | AA6: Score Range
A7: Client14 | B7: 45758 | C7: 4 | D7: 54.5 | E7: 126650 | G7: Client6 | H7: 105 | I7: 36400 | J7: 1 | K7: 45702 | L7: =$M$2-K7 -> 107 | N7: =1/L7 -> 0.0093457944 | O7: =N7/MAX($N$2:$N$82) -> 0.028037383 | P7: =J7/MAX($J$2:$J$82) -> 0.023255814 | Q7: =H7/MAX($H$2:$H$82) -> 0.1793339 | R7: =I7/MAX($I$2:$I$82) -> 0.028122224 | S7: =SUM(N7:R7) -> 0.26809512 | T7: =T6+1 -> 6 | U7: Client57 | V7: 1.3502047 | W7: =IF(V7>=1,"Loyal",IF(V7>=0.4,"Potential Loyalist",IF(V7>=0.15,"Need Attention","At Risk"))) -> Loyal | Z7: Loyal | AA7: ≥ 1.0
A8: Client15 | B8: 45732 | C8: 3 | D8: 42 | E8: 70000 | G8: Client7 | H8: 5 | I8: 23500 | J8: 1 | K8: 45697 | L8: =$M$2-K8 -> 112 | N8: =1/L8 -> 0.0089285714 | O8: =N8/MAX($N$2:$N$82) -> 0.026785714 | P8: =J8/MAX($J$2:$J$82) -> 0.023255814 | Q8: =H8/MAX($H$2:$H$82) -> 0.0085397096 | R8: =I8/MAX($I$2:$I$82) -> 0.018155831 | S8: =SUM(N8:R8) -> 0.08566564 | T8: =T7+1 -> 7 | U8: Client30 | V8: 1.3336612 | W8: =IF(V8>=1,"Loyal",IF(V8>=0.4,"Potential Loyalist",IF(V8>=0.15,"Need Attention","At Risk"))) -> Loyal | Z8: Potential Loyalist | AA8: 0.40 – 0.99
A9: Client16 | B9: 45749 | C9: 1 | D9: 7 | E9: 32900 | G9: Client8 | H9: 40 | I9: 136400 | J9: 5 | K9: 45785 | L9: =$M$2-K9 -> 24 | N9: =1/L9 -> 0.041666667 | O9: =N9/MAX($N$2:$N$82) -> 0.125 | P9: =J9/MAX($J$2:$J$82) -> 0.11627907 | Q9: =H9/MAX($H$2:$H$82) -> 0.068317677 | R9: =I9/MAX($I$2:$I$82) -> 0.10538108 | S9: =SUM(N9:R9) -> 0.45664449 | T9: =T8+1 -> 8 | U9: Client65 | V9: 1.267116 | W9: =IF(V9>=1,"Loyal",IF(V9>=0.4,"Potential Loyalist",IF(V9>=0.15,"Need Attention","At Risk"))) -> Loyal | Z9: Need Attention | AA9: 0.15 – 0.39
A10: Client17 | B10: 45778 | C10: 4 | D10: 66.5 | E10: 132500 | G10: Client9 | H10: 12 | I10: 28200 | J10: 1 | K10: 45749 | L10: =$M$2-K10 -> 60 | N10: =1/L10 -> 0.016666667 | O10: =N10/MAX($N$2:$N$82) -> 0.05 | P10: =J10/MAX($J$2:$J$82) -> 0.023255814 | Q10: =H10/MAX($H$2:$H$82) -> 0.020495303 | R10: =I10/MAX($I$2:$I$82) -> 0.021786997 | S10: =SUM(N10:R10) -> 0.13220478 | T10: =T9+1 -> 9 | U10: Client4 | V10: 1.0174446 | W10: =IF(V10>=1,"Loyal",IF(V10>=0.4,"Potential Loyalist",IF(V10>=0.15,"Need Attention","At Risk"))) -> Loyal | Z10: At Risk | AA10: < 0.15
A11: Client18 | B11: 45730 | C11: 2 | D11: 55.5 | E11: 50000 | G11: Client10 | H11: 47 | I11: 56400 | J11: 3 | K11: 45696 | L11: =$M$2-K11 -> 113 | N11: =1/L11 -> 0.0088495575 | O11: =N11/MAX($N$2:$N$82) -> 0.026548673 | P11: =J11/MAX($J$2:$J$82) -> 0.069767442 | Q11: =H11/MAX($H$2:$H$82) -> 0.080273271 | R11: =I11/MAX($I$2:$I$82) -> 0.043573995 | S11: =SUM(N11:R11) -> 0.22901294 | T11: =T10+1 -> 10 | U11: Client41 | V11: 0.96585029 | W11: =IF(V11>=1,"Loyal",IF(V11>=0.4,"Potential Loyalist",IF(V11>=0.15,"Need Attention","At Risk"))) -> Potential Loyalist
A12: Client19 | B12: 45790 | C12: 3 | D12: 63 | E12: 103750 | G12: Client11 | H12: 42 | I12: 32900 | J12: 1 | K12: 45783 | L12: =$M$2-K12 -> 26 | N12: =1/L12 -> 0.038461538 | O12: =N12/MAX($N$2:$N$82) -> 0.11538462 | P12: =J12/MAX($J$2:$J$82) -> 0.023255814 | Q12: =H12/MAX($H$2:$H$82) -> 0.071733561 | R12: =I12/MAX($I$2:$I$82) -> 0.025418164 | S12: =SUM(N12:R12) -> 0.27425369 | T12: =T11+1 -> 11 | U12: Client73 | V12: 0.96007609 | W12: =IF(V12>=1,"Loyal",IF(V12>=0.4,"Potential Loyalist",IF(V12>=0.15,"Need Attention","At Risk"))) -> Potential Loyalist
A13: Client2 | B13: 45698 | C13: 2 | D13: 9 | E13: 45000 | G13: Client12 | H13: 16 | I13: 37600 | J13: 1 | K13: 45764 | L13: =$M$2-K13 -> 45 | N13: =1/L13 -> 0.022222222 | O13: =N13/MAX($N$2:$N$82) -> 0.066666667 | P13: =J13/MAX($J$2:$J$82) -> 0.023255814 | Q13: =H13/MAX($H$2:$H$82) -> 0.027327071 | R13: =I13/MAX($I$2:$I$82) -> 0.02904933 | S13: =SUM(N13:R13) -> 0.1685211 | T13: =T12+1 -> 12 | U13: Client47 | V13: 0.79993552 | W13: =IF(V13>=1,"Loyal",IF(V13>=0.4,"Potential Loyalist",IF(V13>=0.15,"Need Attention","At Risk"))) -> Potential Loyalist
A14: Client20 | B14: 45749 | C14: 3 | D14: 47.5 | E14: 54800 | G14: Client13 | H14: 4 | I14: 20000 | J14: 1 | K14: 45780 | L14: =$M$2-K14 -> 29 | N14: =1/L14 -> 0.034482759 | O14: =N14/MAX($N$2:$N$82) -> 0.10344828 | P14: =J14/MAX($J$2:$J$82) -> 0.023255814 | Q14: =H14/MAX($H$2:$H$82) -> 0.0068317677 | R14: =I14/MAX($I$2:$I$82) -> 0.015451771 | S14: =SUM(N14:R14) -> 0.18347039 | T14: =T13+1 -> 13 | U14: Client63 | V14: 0.75986304 | W14: =IF(V14>=1,"Loyal",IF(V14>=0.4,"Potential Loyalist",IF(V14>=0.15,"Need Attention","At Risk"))) -> Potential Loyalist
A15: Client21 | B15: 45692 | C15: 2 | D15: 10.5 | E15: 54600 | G15: Client14 | H15: 54.5 | I15: 126650 | J15: 4 | K15: 45758 | L15: =$M$2-K15 -> 51 | N15: =1/L15 -> 0.019607843 | O15: =N15/MAX($N$2:$N$82) -> 0.058823529 | P15: =J15/MAX($J$2:$J$82) -> 0.093023256 | Q15: =H15/MAX($H$2:$H$82) -> 0.093082835 | R15: =I15/MAX($I$2:$I$82) -> 0.097848341 | S15: =SUM(N15:R15) -> 0.3623858 | T15: =T14+1 -> 14 | U15: Client36 | V15: 0.74195589 | W15: =IF(V15>=1,"Loyal",IF(V15>=0.4,"Potential Loyalist",IF(V15>=0.15,"Need Attention","At Risk"))) -> Potential Loyalist
A16: Client22 | B16: 45794 | C16: 3 | D16: 26 | E16: 60000 | G16: Client15 | H16: 42 | I16: 70000 | J16: 3 | K16: 45732 | L16: =$M$2-K16 -> 77 | N16: =1/L16 -> 0.012987013 | O16: =N16/MAX($N$2:$N$82) -> 0.038961039 | P16: =J16/MAX($J$2:$J$82) -> 0.069767442 | Q16: =H16/MAX($H$2:$H$82) -> 0.071733561 | R16: =I16/MAX($I$2:$I$82) -> 0.054081199 | S16: =SUM(N16:R16) -> 0.24753025 | T16: =T15+1 -> 15 | U16: Client53 | V16: 0.74087427 | W16: =IF(V16>=1,"Loyal",IF(V16>=0.4,"Potential Loyalist",IF(V16>=0.15,"Need Attention","At Risk"))) -> Potential Loyalist
A17: Client23 | B17: 45804 | C17: 24 | D17: 585.5 | E17: 699200 | G17: Client16 | H17: 7 | I17: 32900 | J17: 1 | K17: 45749 | L17: =$M$2-K17 -> 60 | N17: =1/L17 -> 0.016666667 | O17: =N17/MAX($N$2:$N$82) -> 0.05 | P17: =J17/MAX($J$2:$J$82) -> 0.023255814 | Q17: =H17/MAX($H$2:$H$82) -> 0.011955594 | R17: =I17/MAX($I$2:$I$82) -> 0.025418164 | S17: =SUM(N17:R17) -> 0.12729624 | T17: =T16+1 -> 16 | U17: Client39 | V17: 0.7017088 | W17: =IF(V17>=1,"Loyal",IF(V17>=0.4,"Potential Loyalist",IF(V17>=0.15,"Need Attention","At Risk"))) -> Potential Loyalist | Y17: Names | Z17: (All)
A18: Client24 | B18: 45761 | C18: 10 | D18: 67 | E18: 226100 | G18: Client17 | H18: 66.5 | I18: 132500 | J18: 4 | K18: 45778 | L18: =$M$2-K18 -> 31 | N18: =1/L18 -> 0.032258065 | O18: =N18/MAX($N$2:$N$82) -> 0.096774194 | P18: =J18/MAX($J$2:$J$82) -> 0.093023256 | Q18: =H18/MAX($H$2:$H$82) -> 0.11357814 | R18: =I18/MAX($I$2:$I$82) -> 0.10236798 | S18: =SUM(N18:R18) -> 0.43800164 | T18: =T17+1 -> 17 | U18: Client80 | V18: 0.66255474 | W18: =IF(V18>=1,"Loyal",IF(V18>=0.4,"Potential Loyalist",IF(V18>=0.15,"Need Attention","At Risk"))) -> Potential Loyalist
A19: Client25 | B19: 45705 | C19: 2 | D19: 12.5 | E19: 62500 | G19: Client18 | H19: 55.5 | I19: 50000 | J19: 2 | K19: 45730 | L19: =$M$2-K19 -> 79 | N19: =1/L19 -> 0.012658228 | O19: =N19/MAX($N$2:$N$82) -> 0.037974684 | P19: =J19/MAX($J$2:$J$82) -> 0.046511628 | Q19: =H19/MAX($H$2:$H$82) -> 0.094790777 | R19: =I19/MAX($I$2:$I$82) -> 0.038629428 | S19: =SUM(N19:R19) -> 0.23056474 | T19: =T18+1 -> 18 | U19: Client24 | V19: 0.60500586 | W19: =IF(V19>=1,"Loyal",IF(V19>=0.4,"Potential Loyalist",IF(V19>=0.15,"Need Attention","At Risk"))) -> Potential Loyalist | Y19: Row Labels | Z19: Count of Segment
A20: Client26 | B20: 45744 | C20: 2 | D20: 8.5 | E20: 39950 | G20: Client19 | H20: 63 | I20: 103750 | J20: 3 | K20: 45790 | L20: =$M$2-K20 -> 19 | N20: =1/L20 -> 0.052631579 | O20: =N20/MAX($N$2:$N$82) -> 0.15789474 | P20: =J20/MAX($J$2:$J$82) -> 0.069767442 | Q20: =H20/MAX($H$2:$H$82) -> 0.10760034 | R20: =I20/MAX($I$2:$I$82) -> 0.080156063 | S20: =SUM(N20:R20) -> 0.46805016 | T20: =T19+1 -> 19 | U20: Client62 | V20: 0.52757616 | W20: =IF(V20>=1,"Loyal",IF(V20>=0.4,"Potential Loyalist",IF(V20>=0.15,"Need Attention","At Risk"))) -> Potential Loyalist | Y20: At Risk | Z20: 14
A21: Client27 | B21: 45764 | C21: 1 | D21: 4.5 | E21: 21150 | G21: Client20 | H21: 47.5 | I21: 54800 | J21: 3 | K21: 45749 | L21: =$M$2-K21 -> 60 | N21: =1/L21 -> 0.016666667 | O21: =N21/MAX($N$2:$N$82) -> 0.05 | P21: =J21/MAX($J$2:$J$82) -> 0.069767442 | Q21: =H21/MAX($H$2:$H$82) -> 0.081127242 | R21: =I21/MAX($I$2:$I$82) -> 0.042337853 | S21: =SUM(N21:R21) -> 0.2598992 | T21: =T20+1 -> 20 | U21: Client42 | V21: 0.51012135 | W21: =IF(V21>=1,"Loyal",IF(V21>=0.4,"Potential Loyalist",IF(V21>=0.15,"Need Attention","At Risk"))) -> Potential Loyalist | Y21: Loyal | Z21: 9
A22: Client28 | B22: 45759 | C22: 2 | D22: 19 | E22: 61100 | G22: Client21 | H22: 10.5 | I22: 54600 | J22: 2 | K22: 45692 | L22: =$M$2-K22 -> 117 | N22: =1/L22 -> 0.0085470085 | O22: =N22/MAX($N$2:$N$82) -> 0.025641026 | P22: =J22/MAX($J$2:$J$82) -> 0.046511628 | Q22: =H22/MAX($H$2:$H$82) -> 0.01793339 | R22: =I22/MAX($I$2:$I$82) -> 0.042183335 | S22: =SUM(N22:R22) -> 0.14081639 | T22: =T21+1 -> 21 | U22: Client19 | V22: 0.46805016 | W22: =IF(V22>=1,"Loyal",IF(V22>=0.4,"Potential Loyalist",IF(V22>=0.15,"Need Attention","At Risk"))) -> Potential Loyalist | Y22: Need Attention | Z22: 41
A23: Client29 | B23: 45780 | C23: 1 | D23: 6 | E23: 28200 | G23: Client22 | H23: 26 | I23: 60000 | J23: 3 | K23: 45794 | L23: =$M$2-K23 -> 15 | N23: =1/L23 -> 0.066666667 | O23: =N23/MAX($N$2:$N$82) -> 0.2 | P23: =J23/MAX($J$2:$J$82) -> 0.069767442 | Q23: =H23/MAX($H$2:$H$82) -> 0.04440649 | R23: =I23/MAX($I$2:$I$82) -> 0.046355313 | S23: =SUM(N23:R23) -> 0.42719591 | T23: =T22+1 -> 22 | U23: Client8 | V23: 0.45664449 | W23: =IF(V23>=1,"Loyal",IF(V23>=0.4,"Potential Loyalist",IF(V23>=0.15,"Need Attention","At Risk"))) -> Potential Loyalist | Y23: Potential Loyalist | Z23: 17
A24: Client3 | B24: 45761 | C24: 2 | D24: 12.5 | E24: 62500 | G24: Client23 | H24: 585.5 | I24: 699200 | J24: 24 | K24: 45804 | L24: =$M$2-K24 -> 5 | N24: =1/L24 -> 0.2 | O24: =N24/MAX($N$2:$N$82) -> 0.6 | P24: =J24/MAX($J$2:$J$82) -> 0.55813953 | Q24: =H24/MAX($H$2:$H$82) -> 1 | R24: =I24/MAX($I$2:$I$82) -> 0.54019392 | S24: =SUM(N24:R24) -> 2.8983335 | T24: =T23+1 -> 23 | U24: Client49 | V24: 0.45184242 | W24: =IF(V24>=1,"Loyal",IF(V24>=0.4,"Potential Loyalist",IF(V24>=0.15,"Need Attention","At Risk"))) -> Potential Loyalist | Y24: Grand Total | Z24: 81
A25: Client30 | B25: 45805 | C25: 5 | D25: 72 | E25: 122200 | G25: Client24 | H25: 67 | I25: 226100 | J25: 10 | K25: 45761 | L25: =$M$2-K25 -> 48 | N25: =1/L25 -> 0.020833333 | O25: =N25/MAX($N$2:$N$82) -> 0.0625 | P25: =J25/MAX($J$2:$J$82) -> 0.23255814 | Q25: =H25/MAX($H$2:$H$82) -> 0.11443211 | R25: =I25/MAX($I$2:$I$82) -> 0.17468227 | S25: =SUM(N25:R25) -> 0.60500586 | T25: =T24+1 -> 24 | U25: Client17 | V25: 0.43800164 | W25: =IF(V25>=1,"Loyal",IF(V25>=0.4,"Potential Loyalist",IF(V25>=0.15,"Need Attention","At Risk"))) -> Potential Loyalist
A26: Client31 | B26: 45790 | C26: 1 | D26: 14 | E26: 32900 | G26: Client25 | H26: 12.5 | I26: 62500 | J26: 2 | K26: 45705 | L26: =$M$2-K26 -> 104 | N26: =1/L26 -> 0.0096153846 | O26: =N26/MAX($N$2:$N$82) -> 0.028846154 | P26: =J26/MAX($J$2:$J$82) -> 0.046511628 | Q26: =H26/MAX($H$2:$H$82) -> 0.021349274 | R26: =I26/MAX($I$2:$I$82) -> 0.048286785 | S26: =SUM(N26:R26) -> 0.15460923 | T26: =T25+1 -> 25 | U26: Client22 | V26: 0.42719591 | W26: =IF(V26>=1,"Loyal",IF(V26>=0.4,"Potential Loyalist",IF(V26>=0.15,"Need Attention","At Risk"))) -> Potential Loyalist
A27: Client32 | B27: 45760 | C27: 1 | D27: 3 | E27: 15000 | G27: Client26 | H27: 8.5 | I27: 39950 | J27: 2 | K27: 45744 | L27: =$M$2-K27 -> 65 | N27: =1/L27 -> 0.015384615 | O27: =N27/MAX($N$2:$N$82) -> 0.046153846 | P27: =J27/MAX($J$2:$J$82) -> 0.046511628 | Q27: =H27/MAX($H$2:$H$82) -> 0.014517506 | R27: =I27/MAX($I$2:$I$82) -> 0.030864913 | S27: =SUM(N27:R27) -> 0.15343251 | T27: =T26+1 -> 26 | U27: Client40 | V27: 0.4190633 | W27: =IF(V27>=1,"Loyal",IF(V27>=0.4,"Potential Loyalist",IF(V27>=0.15,"Need Attention","At Risk"))) -> Potential Loyalist
A28: Client33 | B28: 45724 | C28: 3 | D28: 13 | E28: 52000 | G28: Client27 | H28: 4.5 | I28: 21150 | J28: 1 | K28: 45764 | L28: =$M$2-K28 -> 45 | N28: =1/L28 -> 0.022222222 | O28: =N28/MAX($N$2:$N$82) -> 0.066666667 | P28: =J28/MAX($J$2:$J$82) -> 0.023255814 | Q28: =H28/MAX($H$2:$H$82) -> 0.0076857387 | R28: =I28/MAX($I$2:$I$82) -> 0.016340248 | S28: =SUM(N28:R28) -> 0.13617069 | T28: =T27+1 -> 27 | U28: Client77 | V28: 0.38287301 | W28: =IF(V28>=1,"Loyal",IF(V28>=0.4,"Potential Loyalist",IF(V28>=0.15,"Need Attention","At Risk"))) -> Need Attention
A29: Client34 | B29: 45780 | C29: 2 | D29: 20 | E29: 61100 | G29: Client28 | H29: 19 | I29: 61100 | J29: 2 | K29: 45759 | L29: =$M$2-K29 -> 50 | N29: =1/L29 -> 0.02 | O29: =N29/MAX($N$2:$N$82) -> 0.06 | P29: =J29/MAX($J$2:$J$82) -> 0.046511628 | Q29: =H29/MAX($H$2:$H$82) -> 0.032450897 | R29: =I29/MAX($I$2:$I$82) -> 0.047205161 | S29: =SUM(N29:R29) -> 0.20616769 | T29: =T28+1 -> 28 | U29: Client54 | V29: 0.37530075 | W29: =IF(V29>=1,"Loyal",IF(V29>=0.4,"Potential Loyalist",IF(V29>=0.15,"Need Attention","At Risk"))) -> Need Attention
A30: Client35 | B30: 45786 | C30: 1 | D30: 7 | E30: 28000 | G30: Client29 | H30: 6 | I30: 28200 | J30: 1 | K30: 45780 | L30: =$M$2-K30 -> 29 | N30: =1/L30 -> 0.034482759 | O30: =N30/MAX($N$2:$N$82) -> 0.10344828 | P30: =J30/MAX($J$2:$J$82) -> 0.023255814 | Q30: =H30/MAX($H$2:$H$82) -> 0.010247652 | R30: =I30/MAX($I$2:$I$82) -> 0.021786997 | S30: =SUM(N30:R30) -> 0.1932215 | T30: =T29+1 -> 29 | U30: Client55 | V30: 0.3631617 | W30: =IF(V30>=1,"Loyal",IF(V30>=0.4,"Potential Loyalist",IF(V30>=0.15,"Need Attention","At Risk"))) -> Need Attention
A31: Client36 | B31: 45803 | C31: 1 | D31: 14 | E31: 36400 | G31: Client30 | H31: 72 | I31: 122200 | J31: 5 | K31: 45805 | L31: =$M$2-K31 -> 4 | N31: =1/L31 -> 0.25 | O31: =N31/MAX($N$2:$N$82) -> 0.75 | P31: =J31/MAX($J$2:$J$82) -> 0.11627907 | Q31: =H31/MAX($H$2:$H$82) -> 0.12297182 | R31: =I31/MAX($I$2:$I$82) -> 0.094410322 | S31: =SUM(N31:R31) -> 1.3336612 | T31: =T30+1 -> 30 | U31: Client14 | V31: 0.3623858 | W31: =IF(V31>=1,"Loyal",IF(V31>=0.4,"Potential Loyalist",IF(V31>=0.15,"Need Attention","At Risk"))) -> Need Attention
A32: Client37 | B32: 45727 | C32: 2 | D32: 29 | E32: 70550 | G32: Client31 | H32: 14 | I32: 32900 | J32: 1 | K32: 45790 | L32: =$M$2-K32 -> 19 | N32: =1/L32 -> 0.052631579 | O32: =N32/MAX($N$2:$N$82) -> 0.15789474 | P32: =J32/MAX($J$2:$J$82) -> 0.023255814 | Q32: =H32/MAX($H$2:$H$82) -> 0.023911187 | R32: =I32/MAX($I$2:$I$82) -> 0.025418164 | S32: =SUM(N32:R32) -> 0.28311148 | T32: =T31+1 -> 31 | U32: Client59 | V32: 0.3506375 | W32: =IF(V32>=1,"Loyal",IF(V32>=0.4,"Potential Loyalist",IF(V32>=0.15,"Need Attention","At Risk"))) -> Need Attention
A33: Client38 | B33: 45739 | C33: 2 | D33: 16 | E33: 51700 | G33: Client32 | H33: 3 | I33: 15000 | J33: 1 | K33: 45760 | L33: =$M$2-K33 -> 49 | N33: =1/L33 -> 0.020408163 | O33: =N33/MAX($N$2:$N$82) -> 0.06122449 | P33: =J33/MAX($J$2:$J$82) -> 0.023255814 | Q33: =H33/MAX($H$2:$H$82) -> 0.0051238258 | R33: =I33/MAX($I$2:$I$82) -> 0.011588828 | S33: =SUM(N33:R33) -> 0.12160112 | T33: =T32+1 -> 32 | U33: Client78 | V33: 0.33481612 | W33: =IF(V33>=1,"Loyal",IF(V33>=0.4,"Potential Loyalist",IF(V33>=0.15,"Need Attention","At Risk"))) -> Need Attention
A34: Client39 | B34: 45791 | C34: 10 | D34: 62 | E34: 182550 | G34: Client33 | H34: 13 | I34: 52000 | J34: 3 | K34: 45724 | L34: =$M$2-K34 -> 85 | N34: =1/L34 -> 0.011764706 | O34: =N34/MAX($N$2:$N$82) -> 0.035294118 | P34: =J34/MAX($J$2:$J$82) -> 0.069767442 | Q34: =H34/MAX($H$2:$H$82) -> 0.022203245 | R34: =I34/MAX($I$2:$I$82) -> 0.040174605 | S34: =SUM(N34:R34) -> 0.17920412 | T34: =T33+1 -> 33 | U34: Client52 | V34: 0.28707691 | W34: =IF(V34>=1,"Loyal",IF(V34>=0.4,"Potential Loyalist",IF(V34>=0.15,"Need Attention","At Risk"))) -> Need Attention
A35: Client4 | B35: 45742 | C35: 11 | D35: 247.5 | E35: 361400 | G35: Client34 | H35: 20 | I35: 61100 | J35: 2 | K35: 45780 | L35: =$M$2-K35 -> 29 | N35: =1/L35 -> 0.034482759 | O35: =N35/MAX($N$2:$N$82) -> 0.10344828 | P35: =J35/MAX($J$2:$J$82) -> 0.046511628 | Q35: =H35/MAX($H$2:$H$82) -> 0.034158839 | R35: =I35/MAX($I$2:$I$82) -> 0.047205161 | S35: =SUM(N35:R35) -> 0.26580666 | T35: =T34+1 -> 34 | U35: Client31 | V35: 0.28311148 | W35: =IF(V35>=1,"Loyal",IF(V35>=0.4,"Potential Loyalist",IF(V35>=0.15,"Need Attention","At Risk"))) -> Need Attention
A36: Client40 | B36: 45794 | C36: 2 | D36: 33 | E36: 64100 | G36: Client35 | H36: 7 | I36: 28000 | J36: 1 | K36: 45786 | L36: =$M$2-K36 -> 23 | N36: =1/L36 -> 0.043478261 | O36: =N36/MAX($N$2:$N$82) -> 0.13043478 | P36: =J36/MAX($J$2:$J$82) -> 0.023255814 | Q36: =H36/MAX($H$2:$H$82) -> 0.011955594 | R36: =I36/MAX($I$2:$I$82) -> 0.02163248 | S36: =SUM(N36:R36) -> 0.23075693 | T36: =T35+1 -> 35 | U36: Client11 | V36: 0.27425369 | W36: =IF(V36>=1,"Loyal",IF(V36>=0.4,"Potential Loyalist",IF(V36>=0.15,"Need Attention","At Risk"))) -> Need Attention
... A82: Client9 | B82: 45749 | C82: 1 | D82: 12 | E82: 28200 | G82: Client81 | H82: 38 | I82: 48500 | J82: 2 | K82: 45693 | L82: =$M$2-K82 -> 116 | N82: =1/L82 -> 0.0086206897 | O82: =N82/MAX($N$2:$N$82) -> 0.025862069 | P82: =J82/MAX($J$2:$J$82) -> 0.046511628 | Q82: =H82/MAX($H$2:$H$82) -> 0.064901793 | R82: =I82/MAX($I$2:$I$82) -> 0.037470545 | S82: =SUM(N82:R82) -> 0.18336672 | T82: =T81+1 -> 81 | U82: Client7 | V82: 0.08566564 | W82: =IF(V82>=1,"Loyal",IF(V82>=0.4,"Potential Loyalist",IF(V82>=0.15,"Need Attention","At Risk"))) -> At Risk
A83: Grand Total | B83: 45806 | C83: 329 | D83: 5264 | E83: 9173950

Sheet Sheet1
A1: Name | B1: Client
A2: Akbar | B2: Client1
A3: Akshith | B3: Client2
A4: altanalt | B4: Client3
A5: Arjun | B5: Client4
A6: B santhosh | B6: Client5
A7: B somaiah | B7: Client6
A8: Bahadhur sing | B8: Client7
A9: balaih | B9: Client8
A10: Balral | B10: Client9
A11: Bepi Ecil | B11: Client10
A12: bharath | B12: Client11
... A82: yadhagiri | B82: Client81

Sheet Transit Mixers
A1: exit | B1: re entry | C1: Driver Name | D1: turn around (hrs) | E1: minutes | F1: site | G1: Daytime | I1: turn around (hrs) | J1: (All)
A2: 0.18472222 | B2: 0.26388889 | C2: Driver8 | D2: 0.079166667 | E2: 114 | F2: Site A | G2: Morning
A3: 0.20138889 | B3: 0.3125 | C3: Driver5 | D3: 0.11111111 | E3: 160 | F3: Site A | G3: Early Morning | I3: Row Labels | J3: Average of minutes | K3: Driver Name | L3: Minutes
A4: 0.20138889 | B4: 0.30555556 | C4: Driver7 | D4: 0.10416667 | E4: 150 | F4: Site A | G4: Early Morning | I4: Afternoon | J4: 160 | K4: Driver1 | L4: 176.66667
A5: 0.20833333 | B5: 0.30555556 | C5: Driver3 | D5: 0.097222222 | E5: 140 | F5: Site A | G5: Early Morning | I5: Early Morning | J5: 150.66667 | K5: Driver2 | L5: 102.22222
A6: 0.21527778 | B6: 0.33333333 | C6: Driver6 | D6: 0.11805556 | E6: 170 | F6: Site A | G6: Early Morning | I6: Evening | J6: 180.25 | K6: Driver3 | L6: 135.625
A7: 0.22291667 | B7: 0.31597222 | C7: Driver2 | D7: 0.093055556 | E7: 134 | F7: Site A | G7: Early Morning | I7: Morning | J7: 105.51724 | K7: Driver4 | L7: 40
A8: 0.27083333 | B8: 0.375 | C8: Driver8 | D8: 0.10416667 | E8: 150 | F8: Site A | G8: Early Morning | I8: Night | J8: 55 | K8: Driver5 | L8: 125
A9: 0.29166667 | B9: 0.375 | C9: Driver7 | D9: 0.083333333 | E9: 120 | F9: Site A | G9: Morning | I9: Grand Total | J9: 129.25926 | K9: Driver6 | L9: 129.375
A10: 0.3125 | B10: 0.48611111 | C10: Driver3 | D10: 0.17361111 | E10: 250 | F10: Site A | G10: Morning | K10: Driver7 | L10: 156.83333
A11: 0.31597222 | B11: 0.41666667 | C11: Driver2 | D11: 0.10069444 | E11: 145 | F11: Site A | G11: Morning | K11: Driver8 | L11: 145.57143
A12: 0.32291667 | B12: 0.41666667 | C12: Driver5 | D12: 0.09375 | E12: 135 | F12: Site A | G12: Morning | K12: Driver9 | L12: 165
A13: 0.33333333 | B13: 0.43055556 | C13: Driver6 | D13: 0.097222222 | E13: 140 | F13: Site A | G13: Morning
A14: 0.375 | B14: 0.51388889 | C14: Driver7 | D14: 0.13888889 | E14: 200 | F14: Site A | G14: Morning
A15: 0.38194444 | B15: 0.52083333 | C15: Driver8 | D15: 0.13888889 | E15: 200 | F15: Site A | G15: Morning
A16: 0.41666667 | B16: 0.54166667 | C16: Driver2 | D16: 0.125 | E16: 180 | F16: Site A | G16: Morning
A17: 0.43055556 | B17: 0.59722222 | C17: Driver5 | D17: 0.16666667 | E17: 240 | F17: Site A | G17: Morning
A18: 0.44097222 | B18: 0.63194444 | C18: Driver6 | D18: 0.19097222 | E18: 275 | F18: Site A | G18: Morning
A19: 0.45833333 | B19: 0.58333333 | C19: Driver3 | D19: 0.125 | E19: 180 | F19: Site A | G19: Morning
A20: 0.48611111 | B20: 0.625 | C20: Driver1 | D20: 0.13888889 | E20: 200 | F20: Site A | G20: Morning
A21: 0.5 | B21: 0.63888889 | C21: Driver9 | D21: 0.13888889 | E21: 200 | F21: Site A | G21: Afternoon
A22: 0.52083333 | B22: 0.64583333 | C22: Driver7 | D22: 0.125 | E22: 180 | F22: Site A | G22: Afternoon
A23: 0.52777778 | B23: 0.65277778 | C23: Driver8 | D23: 0.125 | E23: 180 | F23: Site A | G23: Afternoon
A24: 0.55555556 | B24: 0.65972222 | C24: Driver2 | D24: 0.10416667 | E24: 150 | F24: Site A | G24: Afternoon
... A55: 0.42361111 | B55: 0.46527778 | C55: Driver6 | D55: 0.041666667 | E55: 60 | F55: Site B | G55: Morning
