Workbook

Sheet Daily Sales
A1: Date | B1: Grade | C1: quantity in m3 | D1: no of transit mixers | E1: total | F1: Client | G1: cement | H1: sand | I1: 12mm | J1: 20mm | K1: flyash | L1: week no
A2: 45689 | B2: M25 | C2: 3.5 | D2: 1 | E2: =C2*D2 -> 3.5 | F2: Client79 | G2: =VLOOKUP(B2,'Grade Formula'!$A$1:$F$7,2,FALSE)*C2*D2/1000 -> 0.805 | H2: =VLOOKUP(B2,'Grade Formula'!$A$1:$F$7,4,FALSE)*C2*D2/1000 -> 2.352 | I2: =VLOOKUP(B2,'Grade Formula'!$A$1:$F$7,6,FALSE)*C2*D2/1000 -> 1.645 | J2: =VLOOKUP(B2,'Grade Formula'!$A$1:$F$7,5,FALSE)*C2*D2/1000 -> 2.0825 | K2: =VLOOKUP(B2,'Grade Formula'!$A$1:$F$7,3,FALSE)*C2*D2/1000 -> 0.35 | L2: =WEEKNUM(A2) -> 5
A3: 45689 | B3: M25 | C3: 2.5 | D3: 1 | E3: =C3*D3 -> 2.5 | F3: Client79 | G3: =VLOOKUP(B3,'Grade Formula'!$A$1:$F$7,2,FALSE)*C3*D3/1000 -> 0.575 | H3: =VLOOKUP(B3,'Grade Formula'!$A$1:$F$7,4,FALSE)*C3*D3/1000 -> 1.68 | I3: =VLOOKUP(B3,'Grade Formula'!$A$1:$F$7,6,FALSE)*C3*D3/1000 -> 1.175 | J3: =VLOOKUP(B3,'Grade Formula'!$A$1:$F$7,5,FALSE)*C3*D3/1000 -> 1.4875 | K3: =VLOOKUP(B3,'Grade Formula'!$A$1:$F$7,3,FALSE)*C3*D3/1000 -> 0.25 | L3: =WEEKNUM(A3) -> 5
A4: 45690 | B4: M25 | C4: 7.25 | D4: 2 | E4: =C4*D4 -> 14.5 | F4: Client19 | G4: =VLOOKUP(B4,'Grade Formula'!$A$1:$F$7,2,FALSE)*C4*D4/1000 -> 3.335 | H4: =VLOOKUP(B4,'Grade Formula'!$A$1:$F$7,4,FALSE)*C4*D4/1000 -> 9.744 | I4: =VLOOKUP(B4,'Grade Formula'!$A$1:$F$7,6,FALSE)*C4*D4/1000 -> 6.815 | J4: =VLOOKUP(B4,'Grade Formula'!$A$1:$F$7,5,FALSE)*C4*D4/1000 -> 8.6275 | K4: =VLOOKUP(B4,'Grade Formula'!$A$1:$F$7,3,FALSE)*C4*D4/1000 -> 1.45 | L4: =WEEKNUM(A4) -> 6
A5: 45692 | B5: M30 | C5: 5.5 | D5: 1 | E5: =C5*D5 -> 5.5 | F5: Client21 | G5: =VLOOKUP(B5,'Grade Formula'!$A$1:$F$7,2,FALSE)*C5*D5/1000 -> 1.375 | H5: =VLOOKUP(B5,'Grade Formula'!$A$1:$F$7,4,FALSE)*C5*D5/1000 -> 4.488 | I5: =VLOOKUP(B5,'Grade Formula'!$A$1:$F$7,6,FALSE)*C5*D5/1000 -> 2.629 | J5: =VLOOKUP(B5,'Grade Formula'!$A$1:$F$7,5,FALSE)*C5*D5/1000 -> 3.223 | K5: =VLOOKUP(B5,'Grade Formula'!$A$1:$F$7,3,FALSE)*C5*D5/1000 -> 0.605 | L5: =WEEKNUM(A5) -> 6
A6: 45692 | B6: M30 | C6: 5 | D6: 1 | E6: =C6*D6 -> 5 | F6: Client21 | G6: =VLOOKUP(B6,'Grade Formula'!$A$1:$F$7,2,FALSE)*C6*D6/1000 -> 1.25 | H6: =VLOOKUP(B6,'Grade Formula'!$A$1:$F$7,4,FALSE)*C6*D6/1000 -> 4.08 | I6: =VLOOKUP(B6,'Grade Formula'!$A$1:$F$7,6,FALSE)*C6*D6/1000 -> 2.39 | J6: =VLOOKUP(B6,'Grade Formula'!$A$1:$F$7,5,FALSE)*C6*D6/1000 -> 2.93 | K6: =VLOOKUP(B6,'Grade Formula'!$A$1:$F$7,3,FALSE)*C6*D6/1000 -> 0.55 | L6: =WEEKNUM(A6) -> 6
A7: 45692 | B7: M20 | C7: 7 | D7: 5 | E7: =C7*D7 -> 35 | F7: Client42 | G7: =VLOOKUP(B7,'Grade Formula'!$A$1:$F$7,2,FALSE)*C7*D7/1000 -> 11.2 | H7: =VLOOKUP(B7,'Grade Formula'!$A$1:$F$7,4,FALSE)*C7*D7/1000 -> 21.98 | I7: =VLOOKUP(B7,'Grade Formula'!$A$1:$F$7,6,FALSE)*C7*D7/1000 -> 16.45 | J7: =VLOOKUP(B7,'Grade Formula'!$A$1:$F$7,5,FALSE)*C7*D7/1000 -> 21 | K7: =VLOOKUP(B7,'Grade Formula'!$A$1:$F$7,3,FALSE)*C7*D7/1000 -> 2.8 | L7: =WEEKNUM(A7) -> 6
A8: 45692 | B8: M20 | C8: 3 | D8: 1 | E8: =C8*D8 -> 3 | F8: Client42 | G8: =VLOOKUP(B8,'Grade Formula'!$A$1:$F$7,2,FALSE)*C8*D8/1000 -> 0.96 | H8: =VLOOKUP(B8,'Grade Formula'!$A$1:$F$7,4,FALSE)*C8*D8/1000 -> 1.884 | I8: =VLOOKUP(B8,'Grade Formula'!$A$1:$F$7,6,FALSE)*C8*D8/1000 -> 1.41 | J8: =VLOOKUP(B8,'Grade Formula'!$A$1:$F$7,5,FALSE)*C8*D8/1000 -> 1.8 | K8: =VLOOKUP(B8,'Grade Formula'!$A$1:$F$7,3,FALSE)*C8*D8/1000 -> 0.24 | L8: =WEEKNUM(A8) -> 6
A9: 45693 | B9: M20 | C9: 7 | D9: 5 | E9: =C9*D9 -> 35 | F9: Client81 | G9: =VLOOKUP(B9,'Grade Formula'!$A$1:$F$7,2,FALSE)*C9*D9/1000 -> 11.2 | H9: =VLOOKUP(B9,'Grade Formula'!$A$1:$F$7,4,FALSE)*C9*D9/1000 -> 21.98 | I9: =VLOOKUP(B9,'Grade Formula'!$A$1:$F$7,6,FALSE)*C9*D9/1000 -> 16.45 | J9: =VLOOKUP(B9,'Grade Formula'!$A$1:$F$7,5,FALSE)*C9*D9/1000 -> 21 | K9: =VLOOKUP(B9,'Grade Formula'!$A$1:$F$7,3,FALSE)*C9*D9/1000 -> 2.8 | L9: =WEEKNUM(A9) -> 6
A10: 45693 | B10: M30 | C10: 3 | D10: 1 | E10: =C10*D10 -> 3 | F10: Client81 | G10: =VLOOKUP(B10,'Grade Formula'!$A$1:$F$7,2,FALSE)*C10*D10/1000 -> 0.75 | H10: =VLOOKUP(B10,'Grade Formula'!$A$1:$F$7,4,FALSE)*C10*D10/1000 -> 2.448 | I10: =VLOOKUP(B10,'Grade Formula'!$A$1:$F$7,6,FALSE)*C10*D10/1000 -> 1.434 | J10: =VLOOKUP(B10,'Grade Formula'!$A$1:$F$7,5,FALSE)*C10*D10/1000 -> 1.758 | K10: =VLOOKUP(B10,'Grade Formula'!$A$1:$F$7,3,FALSE)*C10*D10/1000 -> 0.33 | L10: =WEEKNUM(A10) -> 6
A11: 45693 | B11: M20 | C11: 7 | D11: 5 | E11: =C11*D11 -> 35 | F11: Client67 | G11: =VLOOKUP(B11,'Grade Formula'!$A$1:$F$7,2,FALSE)*C11*D11/1000 -> 11.2 | H11: =VLOOKUP(B11,'Grade Formula'!$A$1:$F$7,4,FALSE)*C11*D11/1000 -> 21.98 | I11: =VLOOKUP(B11,'Grade Formula'!$A$1:$F$7,6,FALSE)*C11*D11/1000 -> 16.45 | J11: =VLOOKUP(B11,'Grade Formula'!$A$1:$F$7,5,FALSE)*C11*D11/1000 -> 21 | K11: =VLOOKUP(B11,'Grade Formula'!$A$1:$F$7,3,FALSE)*C11*D11/1000 -> 2.8 | L11: =WEEKNUM(A11) -> 6
A12: 45693 | B12: M15 | C12: 6 | D12: 1 | E12: =C12*D12 -> 6 | F12: Client60 | G12: =VLOOKUP(B12,'Grade Formula'!$A$1:$F$7,2,FALSE)*C12*D12/1000 -> 1.56 | H12: =VLOOKUP(B12,'Grade Formula'!$A$1:$F$7,4,FALSE)*C12*D12/1000 -> 4.302 | I12: =VLOOKUP(B12,'Grade Formula'!$A$1:$F$7,6,FALSE)*C12*D12/1000 -> 2.88 | J12: =VLOOKUP(B12,'Grade Formula'!$A$1:$F$7,5,FALSE)*C12*D12/1000 -> 3.78 | K12: =VLOOKUP(B12,'Grade Formula'!$A$1:$F$7,3,FALSE)*C12*D12/1000 -> 0 | L12: =WEEKNUM(A12) -> 6
A13: 45696 | B13: M20 | C13: 7 | D13: 2 | E13: =C13*D13 -> 14 | F13: Client47 | G13: =VLOOKUP(B13,'Grade Formula'!$A$1:$F$7,2,FALSE)*C13*D13/1000 -> 4.48 | H13: =VLOOKUP(B13,'Grade Formula'!$A$1:$F$7,4,FALSE)*C13*D13/1000 -> 8.792 | I13: =VLOOKUP(B13,'Grade Formula'!$A$1:$F$7,6,FALSE)*C13*D13/1000 -> 6.58 | J13: =VLOOKUP(B13,'Grade Formula'!$A$1:$F$7,5,FALSE)*C13*D13/1000 -> 8.4 | K13: =VLOOKUP(B13,'Grade Formula'!$A$1:$F$7,3,FALSE)*C13*D13/1000 -> 1.12 | L13: =WEEKNUM(A13) -> 6
... A330: 45806 | B330: M30 | C330: 6 | D330: 4 | E330: =C330*D330 -> 24 | F330: Client72 | G330: =VLOOKUP(B330,'Grade Formula'!$A$1:$F$7,2,FALSE)*C330*D330/1000 -> 6 | H330: =VLOOKUP(B330,'Grade Formula'!$A$1:$F$7,4,FALSE)*C330*D330/1000 -> 19.584 | I330: =VLOOKUP(B330,'Grade Formula'!$A$1:$F$7,6,FALSE)*C330*D330/1000 -> 11.472 | J330: =VLOOKUP(B330,'Grade Formula'!$A$1:$F$7,5,FALSE)*C330*D330/1000 -> 14.064 | K330: =VLOOKUP(B330,'Grade Formula'!$A$1:$F$7,3,FALSE)*C330*D330/1000 -> 2.64 | L330: =WEEKNUM(A330) -> 22
D331: =SUM(D2:D330) -> 847 | E331: =SUM(E2:E330) -> 5264

Sheet Grade Formula
A1: Mix Designation | B1: Cement (kg/m³) | C1: Flyash(kg/m³) | D1: Sand (kg/m³) | E1: 20mm Coarse Agg. (kg/m³) | F1: 12.5mm Coarse Agg. (kg/m³) | G1: cost per cubic meter
A2: M10 | B2: 210 | C2: 0 | D2: 773 | E2: 660 | F2: 490 | G2: 4000
A3: M15 | B3: 260 | C3: 0 | D3: 717 | E3: 630 | F3: 480 | G3: 4300
A4: M20 | B4: 320 | C4: 80 | D4: 628 | E4: 600 | F4: 470 | G4: 4700
A5: M25 | B5: 230 | C5: 100 | D5: 672 | E5: 595 | F5: 470 | G5: 5000
A6: M30 | B6: 250 | C6: 110 | D6: 816 | E6: 586 | F6: 478 | G6: 5200
A7: M35 | B7: 265 | C7: 115 | D7: 790 | E7: 580 | F7: 470 | G7: 5450

Sheet transit mixers
A1: Vehicle no | B1: exit | C1: re entry | D1: Drive Name | E1: turn around time | F1: minutes | G1: site | H1: Daytime
A2: 6313 | B2: 0.18472222 | C2: 0.26388889 | D2: Driver8 | E2: =C2-B2 -> 0.079166667 | F2: 114 | G2: Site A | H2: =H17 -> Morning
A3: 6590 | B3: 0.20138889 | C3: 0.3125 | D3: Driver5 | E3: =C3-B3 -> 0.11111111 | F3: 160 | G3: Site A | H3: =IF(AND(B3>=TIME(3,0,0), B3<TIME(7,0,0)),"Early Morning", IF(AND(B3>=TIME(7,0,0), B3<TIME(12,0,0)),"Morning", IF(AND(B3>=TIME(12,0,0), B3<TIME(17,0,0)),"Afternoon", IF(AND(B3>=TIME(17,0,0), B3<TIME(21,0,0)),"Evening","Night")))) -> Early Morning
A4: 6316 | B4: 0.20138889 | C4: 0.30555556 | D4: Driver7 | E4: =C4-B4 -> 0.10416667 | F4: 150 | G4: Site A | H4: =IF(AND(B4>=TIME(3,0,0), B4<TIME(7,0,0)),"Early Morning", IF(AND(B4>=TIME(7,0,0), B4<TIME(12,0,0)),"Morning", IF(AND(B4>=TIME(12,0,0), B4<TIME(17,0,0)),"Afternoon", IF(AND(B4>=TIME(17,0,0), B4<TIME(21,0,0)),"Evening","Night")))) -> Early Morning
A5: 6591 | B5: 0.20833333 | C5: 0.30555556 | D5: Driver3 | E5: =C5-B5 -> 0.097222222 | F5: 140 | G5: Site A | H5: =IF(AND(B5>=TIME(3,0,0), B5<TIME(7,0,0)),"Early Morning", IF(AND(B5>=TIME(7,0,0), B5<TIME(12,0,0)),"Morning", IF(AND(B5>=TIME(12,0,0), B5<TIME(17,0,0)),"Afternoon", IF(AND(B5>=TIME(17,0,0), B5<TIME(21,0,0)),"Evening","Night")))) -> Early Morning
A6: 6892 | B6: 0.21527778 | C6: 0.33333333 | D6: Driver6 | E6: =C6-B6 -> 0.11805556 | F6: 170 | G6: Site A | H6: =IF(AND(B6>=TIME(3,0,0), B6<TIME(7,0,0)),"Early Morning", IF(AND(B6>=TIME(7,0,0), B6<TIME(12,0,0)),"Morning", IF(AND(B6>=TIME(12,0,0), B6<TIME(17,0,0)),"Afternoon", IF(AND(B6>=TIME(17,0,0), B6<TIME(21,0,0)),"Evening","Night")))) -> Early Morning
A7: 6315 | B7: 0.22291667 | C7: 0.31597222 | D7: Driver2 | E7: =C7-B7 -> 0.093055556 | F7: 134 | G7: Site A | H7: =IF(AND(B7>=TIME(3,0,0), B7<TIME(7,0,0)),"Early Morning", IF(AND(B7>=TIME(7,0,0), B7<TIME(12,0,0)),"Morning", IF(AND(B7>=TIME(12,0,0), B7<TIME(17,0,0)),"Afternoon", IF(AND(B7>=TIME(17,0,0), B7<TIME(21,0,0)),"Evening","Night")))) -> Early Morning
A8: 6313 | B8: 0.27083333 | C8: 0.375 | D8: Driver8 | E8: =C8-B8 -> 0.10416667 | F8: 150 | G8: Site A | H8: =IF(AND(B8>=TIME(3,0,0), B8<TIME(7,0,0)),"Early Morning", IF(AND(B8>=TIME(7,0,0), B8<TIME(12,0,0)),"Morning", IF(AND(B8>=TIME(12,0,0), B8<TIME(17,0,0)),"Afternoon", IF(AND(B8>=TIME(17,0,0), B8<TIME(21,0,0)),"Evening","Night")))) -> Early Morning
A9: 6316 | B9: 0.29166667 | C9: 0.375 | D9: Driver7 | E9: =C9-B9 -> 0.083333333 | F9: 120 | G9: Site A | H9: =IF(AND(B9>=TIME(3,0,0), B9<TIME(7,0,0)),"Early Morning", IF(AND(B9>=TIME(7,0,0), B9<TIME(12,0,0)),"Morning", IF(AND(B9>=TIME(12,0,0), B9<TIME(17,0,0)),"Afternoon", IF(AND(B9>=TIME(17,0,0), B9<TIME(21,0,0)),"Evening","Night")))) -> Morning
A10: 6591 | B10: 0.3125 | C10: 0.48611111 | D10: Driver3 | E10: =C10-B10 -> 0.17361111 | F10: 250 | G10: Site A | H10: =IF(AND(B10>=TIME(3,0,0), B10<TIME(7,0,0)),"Early Morning", IF(AND(B10>=TIME(7,0,0), B10<TIME(12,0,0)),"Morning", IF(AND(B10>=TIME(12,0,0), B10<TIME(17,0,0)),"Afternoon", IF(AND(B10>=TIME(17,0,0), B10<TIME(21,0,0)),"Evening","Night")))) -> Morning
A11: 6315 | B11: 0.31597222 | C11: 0.41666667 | D11: Driver2 | E11: =C11-B11 -> 0.10069444 | F11: 145 | G11: Site A | H11: =IF(AND(B11>=TIME(3,0,0), B11<TIME(7,0,0)),"Early Morning", IF(AND(B11>=TIME(7,0,0), B11<TIME(12,0,0)),"Morning", IF(AND(B11>=TIME(12,0,0), B11<TIME(17,0,0)),"Afternoon", IF(AND(B11>=TIME(17,0,0), B11<TIME(21,0,0)),"Evening","Night")))) -> Morning
A12: 6590 | B12: 0.32291667 | C12: 0.41666667 | D12: Driver5 | E12: =C12-B12 -> 0.09375 | F12: 135 | G12: Site A | H12: =IF(AND(B12>=TIME(3,0,0), B12<TIME(7,0,0)),"Early Morning", IF(AND(B12>=TIME(7,0,0), B12<TIME(12,0,0)),"Morning", IF(AND(B12>=TIME(12,0,0), B12<TIME(17,0,0)),"Afternoon", IF(AND(B12>=TIME(17,0,0), B12<TIME(21,0,0)),"Evening","Night")))) -> Morning
A13: 6892 | B13: 0.33333333 | C13: 0.43055556 | D13: Driver6 | E13: =C13-B13 -> 0.097222222 | F13: 140 | G13: Site A | H13: =IF(AND(B13>=TIME(3,0,0), B13<TIME(7,0,0)),"Early Morning", IF(AND(B13>=TIME(7,0,0), B13<TIME(12,0,0)),"Morning", IF(AND(B13>=TIME(12,0,0), B13<TIME(17,0,0)),"Afternoon", IF(AND(B13>=TIME(17,0,0), B13<TIME(21,0,0)),"Evening","Night")))) -> Morning
A14: 6316 | B14: 0.375 | C14: 0.51388889 | D14: Driver7 | E14: =C14-B14 -> 0.13888889 | F14: 200 | G14: Site A | H14: =IF(AND(B14>=TIME(3,0,0), B14<TIME(7,0,0)),"Early Morning", IF(AND(B14>=TIME(7,0,0), B14<TIME(12,0,0)),"Morning", IF(AND(B14>=TIME(12,0,0), B14<TIME(17,0,0)),"Afternoon", IF(AND(B14>=TIME(17,0,0), B14<TIME(21,0,0)),"Evening","Night")))) -> Morning
... A55: 6313 | B55: 0.42361111 | C55: 0.46527778 | D55: Driver6 | E55: =C55-B55 -> 0.041666667 | F55: 60 | G55: Site B | H55: =IF(AND(B55>=TIME(3,0,0), B55<TIME(7,0,0)),"Early Morning", IF(AND(B55>=TIME(7,0,0), B55<TIME(12,0,0)),"Morning", IF(AND(B55>=TIME(12,0,0), B55<TIME(17,0,0)),"Afternoon", IF(AND(B55>=TIME(17,0,0), B55<TIME(21,0,0)),"Evening","Night")))) -> Morning

Sheet Descriptive Sats
A1: Row Labels | B1: Sum of cement | C1: Sum of sand | D1: Sum of 20mm | E1: Sum of 12mm | F1: Sum of flyash | G1: Sum of total
A2: 45689 | B2: 1.38 | C2: 4.032 | D2: 3.57 | E2: 2.82 | F2: 0.6 | G2: 6 | R2: TAT(minutes)
A3: 45690 | B3: 3.335 | C3: 9.744 | D3: 8.6275 | E3: 6.815 | F3: 1.45 | G3: 14.5 | R3: 114
A4: 45692 | B4: 14.785 | C4: 32.432 | D4: 28.953 | E4: 22.879 | F4: 4.195 | G4: 48.5 | R4: 160
A5: 45693 | B5: 24.71 | C5: 50.71 | D5: 47.538 | E5: 37.214 | F5: 5.93 | G5: 79 | R5: 150
A6: 45696 | B6: 26.64 | C6: 62.137 | D6: 56.362 | E6: 43.716 | F6: 5.89 | G6: 92 | R6: 140
A7: 45697 | B7: 24.01 | C7: 54.201 | D7: 48.524 | E7: 38.087 | F7: 6.3 | G7: 80.5 | J7: STATS | K7: Cement | L7: Sand | M7: 20mm Aggregates | N7: 12.5mm Aggregates | O7: Flyash | P7: Concrete Produced | R7: 170
A8: 45698 | B8: 11.03 | C8: 23.632 | D8: 22.155 | E8: 17.39 | F8: 3.14 | G8: 37 | J8: Count | K8: =COUNT(B2:B98) -> 97 | L8: =COUNT(C2:C98) -> 97 | M8: =COUNT(D2:D98) -> 97 | N8: =COUNT(E2:E98) -> 97 | O8: =COUNT(F2:F98) -> 97 | P8: =COUNT(G2:G98) -> 97 | R8: 134 | T8: Count | U8: Mean | V8: Std | W8: Min | X8: Max | Y8: Median | Z8: Sum | AA8: Var | AB8: Range | AC8: Mode
A9: 45699 | B9: 9.24 | C9: 27.244 | D9: 20.608 | E9: 16.674 | F9: 3.64 | G9: 35 | J9: Mean | K9: =AVERAGE(B2:B98) -> 13.952397 | L9: =AVERAGE(C2:C98) -> 39.33482 | M9: =AVERAGE(D2:D98) -> 32.523781 | N9: =AVERAGE(E2:E98) -> 25.768289 | O9: =AVERAGE(F2:F98) -> 4.6490722 | P9: =AVERAGE(G2:G98) -> 54.268041 | R9: 150 | T9: =COUNT(R3:R56) -> 54 | U9: =AVERAGE(R3:R56) -> 129.25926 | V9: =STDEV(R3:R56) -> 67.123425 | W9: =MIN(R3:R56) -> 10 | X9: =MAX(R3:R56) -> 275 | Y9: =MEDIAN(R3:R56) -> 140 | Z9: =SUM(R3:R56) -> 6980 | AA9: =VAR(R3:R56) -> 4505.5542 | AB9: =X9-W9 -> 265 | AC9: =MODE(R3:R56) -> 180
A10: 45700 | B10: 22.75 | C10: 74.256 | D10: 53.326 | E10: 43.498 | F10: 10.01 | G10: 91 | J10: Std | K10: =STDEV(B2:B98) -> 10.39205 | L10: =STDEV(C2:C98) -> 31.807365 | M10: =STDEV(D2:D98) -> 25.199578 | N10: =STDEV(E2:E98) -> 20.126738 | O10: =STDEV(F2:F98) -> 4.410457 | P10: =STDEV(G2:G98) -> 42.381011 | R10: 120
A11: 45701 | B11: 13.125 | C11: 42.84 | D11: 30.765 | E11: 25.095 | F11: 5.775 | G11: 52.5 | J11: Min | K11: =MIN(B2:B98) -> 1.25 | L11: =MIN(C2:C98) -> 2.512 | M11: =MIN(D2:D98) -> 2.4 | N11: =MIN(E2:E98) -> 1.88 | O11: =MIN(F2:F98) -> 0 | P11: =MIN(G2:G98) -> 4 | R11: 250
A12: 45702 | B12: 36.05 | C12: 115.3635 | D12: 84.861 | E12: 68.628 | F12: 13.86 | G12: 143.5 | J12: Max | K12: =MAX(B2:B98) -> 57 | L12: =MAX(C2:C98) -> 186.048 | M12: =MAX(D2:D98) -> 142.8 | N12: =MAX(E2:E98) -> 112.8 | O12: =MAX(F2:F98) -> 25.08 | P12: =MAX(G2:G98) -> 240 | R12: 145
A13: 45703 | B13: 3.475 | C13: 10.752 | D13: 8.5645 | E13: 6.871 | F13: 1.52 | G13: 14.5 | J13: Median | K13: =MEDIAN(B2:B98) -> 11.33 | L13: =MEDIAN(C2:C98) -> 32.889 | M13: =MEDIAN(D2:D98) -> 26.4 | N13: =MEDIAN(E2:E98) -> 20.741 | O13: =MEDIAN(F2:F98) -> 3.5 | P13: =MEDIAN(G2:G98) -> 43.5 | R13: 135
A14: 45704 | B14: 1.955 | C14: 5.712 | D14: 5.0575 | E14: 3.995 | F14: 0.85 | G14: 8.5 | J14: Sum | K14: =SUM(B2:B98) -> 1353.3825 | L14: =SUM(C2:C98) -> 3815.4775 | M14: =SUM(D2:D98) -> 3154.8067 | N14: =SUM(E2:E98) -> 2499.524 | O14: =SUM(F2:F98) -> 450.96 | P14: =SUM(G2:G98) -> 5264 | R14: 140
A15: 45705 | B15: 9.2 | C15: 26.88 | D15: 23.8 | E15: 18.8 | F15: 4 | G15: 40 | J15: Var | K15: =VAR(B2:B98) -> 107.99469 | L15: =VAR(C2:C98) -> 1011.7085 | M15: =VAR(D2:D98) -> 635.01871 | N15: =VAR(E2:E98) -> 405.08557 | O15: =VAR(F2:F98) -> 19.452131 | P15: =VAR(G2:G98) -> 1796.1501 | R15: 200
A16: 45706 | B16: 9.94 | C16: 22.596 | D16: 20.93 | E16: 16.45 | F16: 3.08 | G16: 35 | J16: Range | K16: =K12-K11 -> 55.75 | L16: =L12-L11 -> 183.536 | M16: =M12-M11 -> 140.4 | N16: =N12-N11 -> 110.92 | O16: =O12-O11 -> 25.08 | P16: =P12-P11 -> 236 | R16: 200
A17: 45707 | B17: 15.4 | C17: 36.4 | D17: 33.46 | E17: 26.32 | F17: 5.04 | G17: 56 | J17: Mode | K17: =MODE(B2:B98) -> 6.72 | L17: =MODE(C2:C98) -> 5.712 | M17: =MODE(D2:D98) -> 12.6 | N17: =MODE(E2:E98) -> 16.45 | O17: =MODE(F2:F98) -> 0 | P17: =MODE(G2:G98) -> 35 | R17: 180
A18: 45708 | B18: 10.71 | C18: 23.296 | D18: 20.902 | E18: 16.506 | F18: 3.01 | G18: 35 | R18: 240
A19: 45709 | B19: 20.835 | C19: 51.3215 | D19: 46.026 | E19: 35.533 | F19: 4.26 | G19: 74.5 | R19: 275
A20: 45710 | B20: 10.61 | C20: 25.052 | D20: 21.418 | E20: 17.024 | F20: 3.27 | G20: 36 | I20: Row Labels | J20: Sum of no of transit mixers | R20: 180
A21: 45711 | B21: 3.09 | C21: 9.456 | D21: 7.69 | E21: 6.15 | F21: 1.35 | G21: 13 | I21: M10 | J21: 52 | R21: 200
A22: 45712 | B22: 6.51 | C22: 15.936 | D22: 13.682 | E22: 10.866 | F22: 2.13 | G22: 23 | I22: M15 | J22: 66 | R22: 200
A23: 45713 | B23: 3.94 | C23: 13.106 | D23: 11.36 | E23: 8.66 | F23: 0.8 | G23: 18 | I23: M20 | J23: 178 | R23: 180
A24: 45714 | B24: 14.435 | C24: 37.357 | D24: 33.3175 | E24: 25.555 | F24: 1.05 | G24: 53.5 | I24: M25 | J24: 241 | R24: 180
A25: 45715 | B25: 10.66 | C25: 29.397 | D25: 25.83 | E25: 19.68 | F25: 0 | G25: 41 | I25: M30 | J25: 305 | R25: 150
A26: 45716 | B26: 12.74 | C26: 35.133 | D26: 30.87 | E26: 23.52 | F26: 0 | G26: 49 | I26: M35 | J26: 5 | R26: 180
A27: 45717 | B27: 18.06 | C27: 51.576 | D27: 43.484 | E27: 33.572 | F27: 1.54 | G27: 70 | I27: Grand Total | J27: 847 | R27: 140
A28: 45718 | B28: 9.1 | C28: 25.095 | D28: 22.05 | E28: 16.8 | F28: 0 | G28: 35 | L28: Grade | M28: No of transit mixers Ordered | R28: 115
A29: 45719 | B29: 6.72 | C29: 13.188 | D29: 12.6 | E29: 9.87 | F29: 1.68 | G29: 21 | L29: M10 | M29: 52 | R29: 145
A30: 45720 | B30: 12.76 | C30: 34.152 | D30: 27.208 | E30: 21.844 | F30: 4.52 | G30: 46 | L30: M15 | M30: 66 | R30: 130
A31: 45722 | B31: 10.99 | C31: 32.956 | D31: 24.71 | E31: 20.02 | F31: 4.41 | G31: 42 | L31: M20 | M31: 178 | R31: 145
A32: 45723 | B32: 17.605 | C32: 43.258 | D32: 36.8635 | E32: 29.308 | F32: 5.76 | G32: 62 | L32: M25 | M32: 241 | R32: 140
A33: 45724 | B33: 14.92 | C33: 34.088 | D33: 30.592 | E33: 23.921 | F33: 3.45 | G33: 50.5 | L33: M30 | M33: 305 | R33: 130
A34: 45725 | B34: 8.05 | C34: 23.52 | D34: 20.825 | E34: 16.45 | F34: 3.5 | G34: 35 | L34: M35 | M34: 5 | R34: 190
A35: 45726 | B35: 1.28 | C35: 2.512 | D35: 2.4 | E35: 1.88 | F35: 0.32 | G35: 4 | R35: 215
A36: 45727 | B36: 5.43 | C36: 16.464 | D36: 13.622 | E36: 10.866 | F36: 2.37 | G36: 23 | R36: 205
A37: 45729 | B37: 1.25 | C37: 4.08 | D37: 2.93 | E37: 2.39 | F37: 0.55 | G37: 5 | R37: 190
A38: 45730 | B38: 12.765 | C38: 37.296 | D38: 33.0225 | E38: 26.085 | F38: 5.55 | G38: 55.5 | R38: 146
A39: 45732 | B39: 17.11 | C39: 52.822 | D39: 45.472 | E39: 35.586 | F39: 6.17 | G39: 75 | R39: 180
A40: 45733 | B40: 4.255 | C40: 12.432 | D40: 11.0075 | E40: 8.695 | F40: 1.85 | G40: 18.5 | R40: 55
...

Sheet Customer segmentation
A1: Client | B1: total concrete ordered | C1: type
A2: Client23 | B2: 585.5 | C2: =IF(B2>200, "High", IF(B2>=70, "Medium", "Low")) -> High
A3: Client60 | B3: 446.5 | C3: =IF(B3>200, "High", IF(B3>=70, "Medium", "Low")) -> High
A4: Client64 | B4: 403 | C4: =IF(B4>200, "High", IF(B4>=70, "Medium", "Low")) -> High | H4: Row Labels | I4: Count of client
A5: Client57 | B5: 342.25 | C5: =IF(B5>200, "High", IF(B5>=70, "Medium", "Low")) -> High | H5: High | I5: 6
A6: Client4 | B6: 247.5 | C6: =IF(B6>200, "High", IF(B6>=70, "Medium", "Low")) -> High | H6: Low | I6: 66
A7: Client65 | B7: 223.5 | C7: =IF(B7>200, "High", IF(B7>=70, "Medium", "Low")) -> High | E7: Row Labels | F7: Sum of total concrete ordered | H7: Medium | I7: 9
A8: Client73 | B8: 189 | C8: =IF(B8>200, "High", IF(B8>=70, "Medium", "Low")) -> Medium | E8: High | F8: 2248.25 | H8: Grand Total | I8: 81
A9: Client72 | B9: 187.5 | C9: =IF(B9>200, "High", IF(B9>=70, "Medium", "Low")) -> Medium | E9: Low | F9: 1841
A10: Client80 | B10: 171.5 | C10: =IF(B10>200, "High", IF(B10>=70, "Medium", "Low")) -> Medium | E10: Medium | F10: 1174.75
A11: Client41 | B11: 168.75 | C11: =IF(B11>200, "High", IF(B11>=70, "Medium", "Low")) -> Medium | E11: Grand Total | F11: 5264 | I11: type | J11: count
A12: Client42 | B12: 112 | C12: =IF(B12>200, "High", IF(B12>=70, "Medium", "Low")) -> Medium | I12: High | J12: 6
A13: Client6 | B13: 105 | C13: =IF(B13>200, "High", IF(B13>=70, "Medium", "Low")) -> Medium | I13: Low | J13: 66
A14: Client47 | B14: 94.5 | C14: =IF(B14>200, "High", IF(B14>=70, "Medium", "Low")) -> Medium | F14: type | G14: concrete | I14: Medium | J14: 9
A15: Client49 | B15: 74.5 | C15: =IF(B15>200, "High", IF(B15>=70, "Medium", "Low")) -> Medium | F15: High | G15: 2248.25
A16: Client30 | B16: 72 | C16: =IF(B16>200, "High", IF(B16>=70, "Medium", "Low")) -> Medium | F16: Low | G16: 1841
A17: Client78 | B17: 68.5 | C17: =IF(B17>200, "High", IF(B17>=70, "Medium", "Low")) -> Low | F17: Medium | G17: 1174.75
A18: Client54 | B18: 68 | C18: =IF(B18>200, "High", IF(B18>=70, "Medium", "Low")) -> Low
A19: Client24 | B19: 67 | C19: =IF(B19>200, "High", IF(B19>=70, "Medium", "Low")) -> Low
A20: Client17 | B20: 66.5 | C20: =IF(B20>200, "High", IF(B20>=70, "Medium", "Low")) -> Low
A21: Client77 | B21: 66 | C21: =IF(B21>200, "High", IF(B21>=70, "Medium", "Low")) -> Low
A22: Client19 | B22: 63 | C22: =IF(B22>200, "High", IF(B22>=70, "Medium", "Low")) -> Low
A23: Client39 | B23: 62 | C23: =IF(B23>200, "High", IF(B23>=70, "Medium", "Low")) -> Low
A24: Client59 | B24: 57 | C24: =IF(B24>200, "High", IF(B24>=70, "Medium", "Low")) -> Low
A25: Client76 | B25: 56 | C25: =IF(B25>200, "High", IF(B25>=70, "Medium", "Low")) -> Low
A26: Client18 | B26: 55.5 | C26: =IF(B26>200, "High", IF(B26>=70, "Medium", "Low")) -> Low
A27: Client14 | B27: 54.5 | C27: =IF(B27>200, "High", IF(B27>=70, "Medium", "Low")) -> Low
A28: Client63 | B28: 52 | C28: =IF(B28>200, "High", IF(B28>=70, "Medium", "Low")) -> Low
A29: Client62 | B29: 50.5 | C29: =IF(B29>200, "High", IF(B29>=70, "Medium", "Low")) -> Low
... A82: Client32 | B82: 3 | C82: =IF(B82>200, "High", IF(B82>=70, "Medium", "Low")) -> Low

Sheet Result and Findings
D2: week No | E2: concrete producerd | F2: 3 week moving Avergae
A3: Row Labels | B3: Sum of total | D3: 5 | E3: 6 | F3: 6
A4: 5 | B4: 6 | D4: 6 | E4: 234 | F4: 234
A5: 6 | B5: 234 | D5: 7 | E5: 454 | F5: =AVERAGE(E3:E5) -> 231.33333
A6: 7 | B6: 454 | D6: 8 | E6: 285 | F6: =AVERAGE(E4:E6) -> 324.33333
A7: 8 | B7: 285 | D7: 9 | E7: 267.5 | F7: =AVERAGE(E5:E7) -> 335.5
A8: 9 | B8: 267.5 | D8: 10 | E8: 256.5 | F8: =AVERAGE(E6:E8) -> 269.66667
A9: 10 | B9: 256.5 | D9: 11 | E9: 122.5 | F9: =AVERAGE(E7:E9) -> 215.5
A10: 11 | B10: 122.5 | D10: 12 | E10: 198 | F10: =AVERAGE(E8:E10) -> 192.33333
A11: 12 | B11: 198 | D11: 13 | E11: 629 | F11: =AVERAGE(E9:E11) -> 316.5
A12: 13 | B12: 629 | D12: 14 | E12: 119 | F12: =AVERAGE(E10:E12) -> 315.33333
A13: 14 | B13: 119 | D13: 15 | E13: 545 | F13: =AVERAGE(E11:E13) -> 431
A14: 15 | B14: 545 | D14: 16 | E14: 288.5 | F14: =AVERAGE(E12:E14) -> 317.5
A15: 16 | B15: 288.5 | D15: 17 | E15: 234.75 | F15: =AVERAGE(E13:E15) -> 356.08333
A16: 17 | B16: 234.75 | D16: 18 | E16: 232 | F16: =AVERAGE(E14:E16) -> 251.75
... A20: 21 | B20: 388.75 | D20: 22 | E20: 195 | F20: =AVERAGE(E18:E20) -> 385.25
A21: 22 | B21: 195
A22: Grand Total | B22: 5264
A23: site | B23: Site A
A25: Row Labels | B25: Average of minutes | D25: Daytime | E25: TAT
A26: Afternoon | B26: 160 | D26: Afternoon | E26: 160
A27: Early Morning | B27: 145.42857 | D27: Early Morning | E27: 145.42857
A28: Evening | B28: 180.25 | D28: Evening | E28: 180.25
A29: Morning | B29: 188.75 | D29: Morning | E29: 188.75
A30: Night | B30: 55
A31: Grand Total | B31: 165.76316
